Workbook

Sheet Work Steps Updated
B1: Must Complete by | C1: 46035
B2: Order Quantity | C2: 400
C4: Time (sec/piece) | D4: Output/Hour | E4: Total Time (sec) | F4: Total Time (min) | G4: Total Time (hours)
B5: 1. CUTTING: | C5: =SUM(C6:C10) -> 97 | D5: =60*60/C5 -> 37.113402 | E5: =SUM(E6:E10) -> 38800 | F5: =SUM(F6:F10) -> 646.66667 | G5: =SUM(G6:G10) -> 10.777778
B6: ﻿﻿﻿Fabric:
B7: Cut the fabric panels. 18s (just cut time, no set-up) | C7: =18*5 -> 90 | D7: =60*60/C7 -> 40 | E7: =C7*$C$2 -> 36000 | F7: =E7/60 -> 600 | G7: =F7/60 -> 10
B8: ﻿﻿﻿Trim:
B9: I. Cut the Velcro pieces. 2s | C9: 2 | D9: =60*60/C9 -> 1800 | E9: =C9*$C$2 -> 800 | F9: =E9/60 -> 13.333333 | G9: =F9/60 -> 0.22222222
B10: II. Cut the zipper. 5s | C10: 5 | D10: =60*60/C10 -> 720 | E10: =C10*$C$2 -> 2000 | F10: =E10/60 -> 33.333333 | G10: =F10/60 -> 0.55555556
A12: Step 1 must be complete prior to step 2 | B12: 2. SILKSCREEN: | C12: =SUM(C13) -> 0 | D12: =SUM(D13) -> #DIV/0! | E12: =SUM(E13) -> 0 | F12: =SUM(F13) -> 0 | G12: =SUM(G13) -> 0
B13: A. N/A | C13: 0 | D13: =60*60/C13 -> #DIV/0! | E13: =C13*$C$2 -> 0 | F13: =E13/60 -> 0 | G13: =F13/60 -> 0
B15: 3. PREP STEPS: | C15: =SUM(C16) -> 7 | D15: =SUM(D16) -> 514.28571 | E15: =SUM(E16) -> 2800 | F15: =SUM(F16) -> 46.666667 | G15: =SUM(G16) -> 0.77777778
B16: A. Sew the USA flag onto the fabric panel. 7s | C16: 7 | D16: =60*60/C16 -> 514.28571 | E16: =C16*$C$2 -> 2800 | F16: =E16/60 -> 46.666667 | G16: =F16/60 -> 0.77777778
A18: Dependent on complettion of 1, 2 | B18: 4. SEWING: | C18: =C20+C24+C32+C41+C47 -> 654 | D18: =D20+D24+D32+D41+D47 -> 3686.1933 | E18: =E20+E24+E32+E41+E47 -> 261600 | F18: =F20+F24+F32+F41+F47 -> 4360 | G18: =G20+G24+G32+G41+G47 -> 72.666667
B20: A. Small Velcro Pocket | C20: =SUM(C21:C22) -> 45 | D20: =SUM(D21:D22) -> 324 | E20: =SUM(E21:E22) -> 18000 | F20: =SUM(F21:F22) -> 300 | G20: =SUM(G21:G22) -> 5
B21: I. Hem the short edges. 20s | C21: 20 | D21: =60*60/C21 -> 180 | E21: =C21*$C$2 -> 8000 | F21: =E21/60 -> 133.33333 | G21: =F21/60 -> 2.2222222
B22: Il. Sew on the hook Velcro. 25s | C22: 25 | D22: =60*60/C22 -> 144 | E22: =C22*$C$2 -> 10000 | F22: =E22/60 -> 166.66667 | G22: =F22/60 -> 2.7777778
B24: B. Connector Strap | C24: =SUM(C25:C30) -> 140 | D24: =SUM(D25:D30) -> 1059.4286 | E24: =SUM(E25:E30) -> 56000 | F24: =SUM(F25:F30) -> 933.33333 | G24: =SUM(G25:G30) -> 15.555556
B25: I. Sew the panel together along the one long side. 12s | C25: 12 | D25: =60*60/C25 -> 300 | E25: =C25*$C$2 -> 4800 | F25: =E25/60 -> 80 | G25: =F25/60 -> 1.3333333
B26: Il. Turn inside-out. 28s | C26: 28 | D26: =60*60/C26 -> 128.57143 | E26: =C26*$C$2 -> 11200 | F26: =E26/60 -> 186.66667 | G26: =F26/60 -> 3.1111111
B27: III. Sew the 2 sides of the connector strap panel. 25s | C27: 25 | D27: =60*60/C27 -> 144 | E27: =C27*$C$2 -> 10000 | F27: =E27/60 -> 166.66667 | G27: =F27/60 -> 2.7777778
B28: IV. Sew the connector strap to the small Velcro pocket, add the loop Velcro. 35s | C28: 35 | D28: =60*60/C28 -> 102.85714 | E28: =C28*$C$2 -> 14000 | F28: =E28/60 -> 233.33333 | G28: =F28/60 -> 3.8888889
B29: V. Close the sides of the small Velcro pocket and cut corners. 15s | C29: 15 | D29: =60*60/C29 -> 240 | E29: =C29*$C$2 -> 6000 | F29: =E29/60 -> 100 | G29: =F29/60 -> 1.6666667
B30: VI. Cut threads turn pocket right side out 25s | C30: 25 | D30: =60*60/C30 -> 144 | E30: =C30*$C$2 -> 10000 | F30: =E30/60 -> 166.66667 | G30: =F30/60 -> 2.7777778
A32: Dependent on complettion of 3 | B32: C. Hanging big pocket | C32: =SUM(C33:C39) -> 127 | D32: =SUM(D33:D39) -> 1599.6218 | E32: =SUM(E33:E39) -> 50800 | F32: =SUM(F33:F39) -> 846.66667 | G32: =SUM(G33:G39) -> 14.111111
B33: I. Hem long side. 17s | C33: 17 | D33: =60*60/C33 -> 211.76471 | E33: =C33*$C$2 -> 6800 | F33: =E33/60 -> 113.33333 | G33: =F33/60 -> 1.8888889
B34: Il. Fold to the marking, and close both sides. 35s | C34: 35 | D34: =60*60/C34 -> 102.85714 | E34: =C34*$C$2 -> 14000 | F34: =E34/60 -> 233.33333 | G34: =F34/60 -> 3.8888889
B35: IlI. Add stitching to the lower corners to create volume turn right side out. 36s | C35: 15 | D35: =60*60/C35 -> 240 | E35: =C35*$C$2 -> 6000 | F35: =E35/60 -> 100 | G35: =F35/60 -> 1.6666667
B36: IV. Turn Right Side out | C36: 16 | D36: =60*60/C36 -> 225 | E36: =C36*$C$2 -> 6400 | F36: =E36/60 -> 106.66667 | G36: =F36/60 -> 1.7777778
B37: V. Sew the center stitch. Had to fold material to find center (NOT MARKED) 20s | C37: 20 | D37: =60*60/C37 -> 180 | E37: =C37*$C$2 -> 8000 | F37: =E37/60 -> 133.33333 | G37: =F37/60 -> 2.2222222
B38: VI. Add straight single-stitching to the top of the pocket. 15s | C38: 15 | D38: =60*60/C38 -> 240 | E38: =C38*$C$2 -> 6000 | F38: =E38/60 -> 100 | G38: =F38/60 -> 1.6666667
B39: VII. Stitch the connector strap to the large pocket. 9s | C39: 9 | D39: =60*60/C39 -> 400 | E39: =C39*$C$2 -> 3600 | F39: =E39/60 -> 60 | G39: =F39/60 -> 1
A41: Dependent on complettion of A, B & C | B41: D. Cushion cover | C41: =SUM(C42:C45) -> 208 | D41: =SUM(D42:D45) -> 416 | E41: =SUM(E42:E45) -> 83200 | F41: =SUM(F42:F45) -> 1386.6667 | G41: =SUM(G42:G45) -> 23.111111
B42: I. Sew the zipper onto the 2 fabric panels. 100s | C42: 100 | D42: =60*60/C42 -> 36 | E42: =C42*$C$2 -> 40000 | F42: =E42/60 -> 666.66667 | G42: =F42/60 -> 11.111111
B43: Il. Cut off extra material and add the zipper pull. 30s | C43: 30 | D43: =60*60/C43 -> 120 | E43: =C43*$C$2 -> 12000 | F43: =E43/60 -> 200 | G43: =F43/60 -> 3.3333333
B44: III. Add closing stitch to both zipper ends. Cut thread. 18s | C44: 18 | D44: =60*60/C44 -> 200 | E44: =C44*$C$2 -> 7200 | F44: =E44/60 -> 120 | G44: =F44/60 -> 2
B45: IV. Sew together Big Hanging Pocket and Connector Strap and Zipper panels. 60s | C45: 60 | D45: =60*60/C45 -> 60 | E45: =C45*$C$2 -> 24000 | F45: =E45/60 -> 400 | G45: =F45/60 -> 6.6666667
A47: Dependent on complettion of D | B47: E. Finishing: | C47: =SUM(C48:C49) -> 134 | D47: =SUM(D48:D49) -> 287.14286 | E47: =SUM(E48:E49) -> 53600 | F47: =SUM(F48:F49) -> 893.33333 | G47: =SUM(G48:G49) -> 14.888889
B48: I. Sew on the side panels. 120s | C48: 120 | D48: =60*60/C48 -> 30 | E48: =C48*$C$2 -> 48000 | F48: =E48/60 -> 800 | G48: =F48/60 -> 13.333333
B49: II. Add ZigZag to the top of the hanging big pocket. 14s | C49: 14 | D49: =60*60/C49 -> 257.14286 | E49: =C49*$C$2 -> 5600 | F49: =E49/60 -> 93.333333 | G49: =F49/60 -> 1.5555556
...

Sheet Production Steps
D1: Monday - 1/12/20225 | K1: Tuesday - 1/13/20225 | R1: Wednesday - 1/14/20225 | Y1: Thursday - 1/15/20225 | AF1: Friday - 1/16/20225 | AM1: Saturday - 1/17/20225 | AT1: Monday - 1/19/20225 | AX1: Tuesday - 1/20/20225
D2: Names | E2: Hours Required | F2: # of People | G2: Start Time | H2: Finish Time | I2: Day Output | J2: Total Output | K2: Names | L2: Hours Required | M2: # of People | N2: Start Time | O2: Finish Time | P2: Day Output | Q2: Total Output | R2: Names | S2: Hours Required | T2: # of People | U2: Start Time | V2: Finish Time | W2: Day Output | X2: Total Output | Y2: Names | Z2: Hours Required | AA2: # of People | AB2: Start Time | AC2: Finish Time | AD2: Day Output | AE2: Total Output | AF2: Names | AG2: Hours Required | AH2: # of People | AI2: Start Time | AJ2: Finish Time | AK2: Day Output | AL2: Total Output | AM2: Names | AN2: Hours Required | AO2: # of People | AP2: Start Time | AQ2: Finish Time | AR2: Day Output | AS2: Total Output | AT2: Names | AU2: # of People | AV2: Day Output | AW2: Total Output | AX2: Names | AY2: # of People | AZ2: Day Output | BA2: Total Output
B3: 1. CUTTING:
B4: ﻿﻿﻿Fabric:
B5: Cut the fabric panels. 18s (just cut time, no set-up)
B6: ﻿﻿﻿Trim:
B7: I. Cut the Velcro pieces. 2s
B8: II. Cut the zipper. 5s
B10: 2. SILKSCREEN:
B11: A. N/A
B13: 3. PREP STEPS:
B14: A. Sew the USA flag onto the fabric panel. 7s | D14: A - Sewing | E14: ='Work Steps Updated'!$G16 -> 0.77777778 | F14: 1 | G14: 0.41666667 | H14: =G14+(E14/F14)/24 -> 0.44907407 | K14: X - Sewing | L14: ='Work Steps Updated'!$G16 -> 0.77777778 | M14: 1 | N14: 0.41666667 | O14: =N14+(L14/M14)/24 -> 0.44907407
B16: 4. SEWING:
B18: A. Small Velcro Pocket
B19: I. Hem the short edges. 20s | D19: B - Sewing | E19: ='Work Steps Updated'!$G21 -> 2.2222222 | F19: 1 | G19: 0.41666667 | H19: =G19+(E19/F19)/24+0.5/24 -> 0.53009259 | R19: B - Sewing | S19: ='Work Steps Updated'!$G21 -> 2.2222222 | T19: 1 | U19: 0.29166667 | V19: =U19+(S19/T19)/24+0.5/24 -> 0.40509259
B20: Il. Sew on the hook Velcro. 25s | D20: B - Sewing | E20: ='Work Steps Updated'!$G22 -> 2.7777778 | F20: 1 | G20: =H19+((5/60)/24) -> 0.53356481 | H20: =G20+(E20/F20)/24 -> 0.64930556 | R20: B - Sewing | S20: ='Work Steps Updated'!$G22 -> 2.7777778 | T20: 1 | U20: =V19+((5/60)/24) -> 0.40856481 | V20: =U20+(S20/T20)/24+0.5/24 -> 0.54513889
B22: B. Connector Strap
B23: I. Sew the panel together along the one long side. 12s | D23: C - Sewing | E23: ='Work Steps Updated'!$G25 -> 1.3333333 | F23: 1 | G23: 0.41666667 | H23: =G23+(E23/F23)/24+0.5/24 -> 0.49305556 | R23: C - Sewing | S23: ='Work Steps Updated'!$G25 -> 1.3333333 | T23: 1 | U23: 0.29166667 | V23: =U23+(S23/T23)/24 -> 0.34722222
B24: Il. Turn inside-out. 28s | D24: F & G - Other | E24: ='Work Steps Updated'!$G26 -> 3.1111111 | F24: 2 | G24: =G23 -> 0.41666667 | H24: =G24+(E24/F24)/24+0.5/24 -> 0.50231481 | R24: F & G - Other | S24: ='Work Steps Updated'!$G26 -> 3.1111111 | T24: 2 | U24: =U23 -> 0.29166667 | V24: =U24+(S24/T24)/24 -> 0.35648148
B25: III. Sew the 2 sides of the connector strap panel. 25s | D25: C & A - Sewing | E25: ='Work Steps Updated'!$G27 -> 2.7777778 | F25: 2 | G25: =H23+((5/60)/24) -> 0.49652778 | H25: =G25+(E25/F25)/24 -> 0.55439815 | R25: C & A - Sewing | S25: ='Work Steps Updated'!$G27 -> 2.7777778 | T25: 2 | U25: =V23+((5/60)/24) -> 0.35069444 | V25: =U25+(S25/T25)/24 -> 0.40856481
B26: IV. Sew the connector strap to the small Velcro pocket, add the loop Velcro. 35s | D26: C & A - Sewing | E26: ='Work Steps Updated'!$G28 -> 3.8888889 | F26: 2 | G26: =H25+((5/60)/24) -> 0.55787037 | H26: =G26+(E26/F26)/24 -> 0.63888889 | R26: C & A - Sewing | S26: ='Work Steps Updated'!$G28 -> 3.8888889 | T26: 2 | U26: =V24+((5/60)/24) -> 0.3599537 | V26: =U26+(S26/T26)/24 -> 0.44097222
B27: V. Close the sides of the small Velcro pocket and cut corners. 15s | D27: B, C & A - Sewing | E27: ='Work Steps Updated'!$G29 -> 1.6666667 | F27: 3 | G27: =H26+((5/60)/24) -> 0.64236111 | H27: =G27+(E27/F27)/24 -> 0.66550926 | R27: C & A - Sewing | S27: ='Work Steps Updated'!$G29 -> 1.6666667 | T27: 2 | U27: =V25+((5/60)/24) -> 0.41203704 | V27: =U27+(S27/T27)/24 -> 0.44675926
B28: VI. Cut threads turn pocket right side out 25s | D28: B, C & A - Sewing | E28: ='Work Steps Updated'!$G30 -> 2.7777778 | F28: 3 | G28: =H27+((5/60)/24) -> 0.66898148 | H28: =G28+(E28/F28)/24 -> 0.70756173 | R28: C & A - Sewing | S28: ='Work Steps Updated'!$G30 -> 2.7777778 | T28: 2 | U28: =V26+((5/60)/24) -> 0.44444444 | V28: =U28+(S28/T28)/24+0.5/24 -> 0.52314815
B30: C. Hanging big pocket
B31: I. Hem long side. 17s | D31: D & E - Sewing | E31: ='Work Steps Updated'!$G33 -> 1.8888889 | F31: 2 | G31: 0.41666667 | H31: =G31+(E31/F31)/24+0.5/24 -> 0.47685185 | R31: D & E - Sewing | S31: ='Work Steps Updated'!$G33 -> 1.8888889 | T31: 2 | U31: 0.29166667 | V31: =U31+(S31/T31)/24+0.5/24 -> 0.35185185
B32: Il. Fold to the marking, and close both sides. 35s | D32: D & E - Sewing | E32: ='Work Steps Updated'!$G34 -> 3.8888889 | F32: 2 | G32: =H31+((5/60)/24) -> 0.48032407 | H32: =G32+(E32/F32)/24 -> 0.56134259 | R32: D & E - Sewing | S32: ='Work Steps Updated'!$G34 -> 3.8888889 | T32: 2 | U32: =V31+((5/60)/24) -> 0.35532407 | V32: =U32+(S32/T32)/24 -> 0.43634259
B33: IlI. Add stitching to the lower corners to create volume turn right side out. 36s | D33: D & E - Sewing | E33: ='Work Steps Updated'!$G35 -> 1.6666667 | F33: 2 | G33: =H32+((5/60)/24) -> 0.56481481 | H33: =G33+(E33/F33)/24 -> 0.59953704 | R33: D & E - Sewing | S33: ='Work Steps Updated'!$G35 -> 1.6666667 | T33: 2 | U33: =V32+((5/60)/24) -> 0.43981481 | V33: =U33+(S33/T33)/24+0.5/24 -> 0.49537037
B34: IV. Turn Right Side out | D34: F & G - Other | E34: ='Work Steps Updated'!$G36 -> 1.7777778 | F34: 2 | G34: =G33 -> 0.56481481 | H34: =G34+(E34/F34)/24 -> 0.60185185 | R34: F & G - Other | S34: ='Work Steps Updated'!$G36 -> 1.7777778 | T34: 2 | U34: =U33 -> 0.43981481 | V34: =U34+(S34/T34)/24+0.5/24 -> 0.49768519
B35: V. Sew the center stitch. Had to fold material to find center (NOT MARKED) 20s | D35: D & E - Sewing | E35: ='Work Steps Updated'!$G37 -> 2.2222222 | F35: 2 | G35: =H33+((5/60)/24) -> 0.60300926 | H35: =G35+(E35/F35)/24 -> 0.64930556 | R35: D & E - Sewing | S35: ='Work Steps Updated'!$G37 -> 2.2222222 | T35: 2 | U35: =V33+((5/60)/24) -> 0.49884259 | V35: =U35+(S35/T35)/24 -> 0.54513889
B36: VI. Add straight single-stitching to the top of the pocket. 15s | D36: D & E - Sewing | E36: ='Work Steps Updated'!$G38 -> 1.6666667 | F36: 2 | G36: =H35+((5/60)/24) -> 0.65277778 | H36: =G36+(E36/F36)/24 -> 0.6875 | R36: A, C, D & E - Sewing | S36: ='Work Steps Updated'!$G38 -> 1.6666667 | T36: 3 | U36: =V34+((5/60)/24) -> 0.50115741 | V36: =U36+(S36/T36)/24 -> 0.52430556
B37: VII. Stitch the connector strap to the large pocket. 9s | D37: D & E - Sewing | E37: ='Work Steps Updated'!$G39 -> 1 | F37: 2 | G37: =H36+((5/60)/24) -> 0.69097222 | H37: =G37+(E37/F37)/24 -> 0.71180556 | R37: A, C, D & E - Sewing | S37: ='Work Steps Updated'!$G39 -> 1 | T37: 4 | U37: =V35+((5/60)/24) -> 0.54861111 | V37: =U37+(S37/T37)/24 -> 0.55902778
B39: D. Cushion cover
B40: I. Sew the zipper onto the 2 fabric panels. 100s | K40: A, B, C, D & E - Sewing | L40: ='Work Steps Updated'!$G42 -> 11.111111 | M40: 5 | N40: 0.29166667 | O40: =N40+(L40/M40)/24 -> 0.38425926 | R40: A, B, C, D & E - Sewing | S40: ='Work Steps Updated'!$G42 -> 11.111111 | T40: 5 | U40: 0.0625 | V40: =U40+(S40/T40)/24 -> 0.15509259
B41: Il. Cut off extra material and add the zipper pull. 30s | K41: A, B, C, D & E - Sewing | L41: ='Work Steps Updated'!$G43 -> 3.3333333 | M41: 5 | N41: =O40+((5/60)/24) -> 0.38773148 | O41: =N41+(L41/M41)/24 -> 0.41550926 | R41: A, B, C, D & E - Sewing | S41: ='Work Steps Updated'!$G43 -> 3.3333333 | T41: 5 | U41: =V40+((5/60)/24) -> 0.15856481 | V41: =U41+(S41/T41)/24 -> 0.18634259
B42: III. Add closing stitch to both zipper ends. Cut thread. 18s | K42: A, B, C, D & E - Sewing | L42: ='Work Steps Updated'!$G44 -> 2 | M42: 5 | N42: =O41+((5/60)/24) -> 0.41898148 | O42: =N42+(L42/M42)/24 -> 0.43564815 | Y42: A, B, C, D & E - Sewing | Z42: ='Work Steps Updated'!$G44 -> 2 | AA42: 5 | AB42: 0.29166667 | AC42: =AB42+(Z42/AA42)/24 -> 0.30833333
B43: IV. Sew together Big Hanging Pocket and Connector Strap and Zipper panels. 60s | K43: A, B, C, D & E - Sewing | L43: ='Work Steps Updated'!$G45 -> 6.6666667 | M43: 5 | N43: =O42+((5/60)/24) -> 0.43912037 | O43: =N43+(L43/M43)/24+0.5/24 -> 0.51550926 | Y43: A, B, C, D & E - Sewing | Z43: ='Work Steps Updated'!$G45 -> 6.6666667 | AA43: 5 | AB43: =AC42+((5/60)/24) -> 0.31180556 | AC43: =AB43+(Z43/AA43)/24 -> 0.36736111
B45: E. Finishing:
B46: I. Sew on the side panels. 120s | K46: A, B, C, D & E - Sewing | L46: ='Work Steps Updated'!$G48 -> 13.333333 | M46: 5 | N46: =O43+((5/60)/24) -> 0.51898148 | O46: =N46+(L46/M46)/24 -> 0.63009259 | Y46: A, B, C, D & E - Sewing | Z46: ='Work Steps Updated'!$G48 -> 13.333333 | AA46: 5 | AB46: =AC43+((5/60)/24) -> 0.37083333 | AC46: =AB46+(Z46/AA46)/24+0.5/24 -> 0.50277778
B47: II. Add ZigZag to the top of the hanging big pocket. 14s | K47: A - Sewing | L47: ='Work Steps Updated'!$G49 -> 1.5555556 | M47: 1 | N47: =O46+((5/60)/24) -> 0.63356481 | O47: =N47+(L47/M47)/24 -> 0.69837963 | Y47: A - Sewing | Z47: ='Work Steps Updated'!$G49 -> 1.5555556 | AA47: 1 | AB47: =AC46+((5/60)/24) -> 0.50625 | AC47: =AB47+(Z47/AA47)/24 -> 0.57106481
B49: 5. INSPECTION:
...
