Workbook
Name file584747SIJFP1247Company47Drawings47INDUSTRIAL3720T47Tenjam4725JAM0013720REV346pdf: BOMInstructions!$G$10

Sheet Prod Plan 0115
E1: Thursday - 1/15/2025 | M1: Friday - 1/16/2025 | U1: Saturday - 1/17/2025
A2: Task ID | B2: FB Task ID | C2: Component | D2: Task | E2: Units to Complete | F2: Names | G2: Hours Required | H2: # of People | I2: Start Time | J2: Finish Time | K2: Day Output | L2: Total Output | M2: Units to Complete | N2: Names | O2: Hours Required | P2: # of People | Q2: Start Time | R2: Finish Time | S2: Day Output | T2: Total Output | U2: Units to Complete | V2: Names | W2: Hours Required | X2: # of People | Y2: Start Time | Z2: Finish Time | AA2: Day Output | AB2: Total Output
A3: ='Work Steps'!C2 -> CFA1 | B3: ='Work Steps'!D2 -> 1 | C3: ='Work Steps'!F2 -> Fabric | D3: ='Work Steps'!G2 -> Cut Fabric | E3: =INDEX(Analysis!$S$5:$Y$35,MATCH('Prod Plan 0115'!$A3,Analysis!$S$5:$S$35,0),4) -> 0 | G3: =INDEX(Analysis!$S$5:$Y$35,MATCH('Prod Plan 0115'!$A3,Analysis!$S$5:$S$35,0),7) -> 0 | L3: =IF(E3=0,0,400-E3+K3) -> 0 | M3: =E3-K3 -> 0 | O3: =M3/INDEX(Analysis!$S$5:$Y$35,MATCH('Prod Plan 0115'!$A3,Analysis!$S$5:$S$35,0),3) -> 0 | T3: =IF(M3=0,0,400-M3+S3) -> 0 | U3: =M3-S3 -> 0 | W3: =U3/INDEX(Analysis!$S$5:$Y$35,MATCH('Prod Plan 0115'!$A3,Analysis!$S$5:$S$35,0),3) -> 0 | AB3: =IF(U3=0,0,400-U3+AA3) -> 0
A4: ='Work Steps'!C3 -> CTA1 | B4: ='Work Steps'!D3 -> 2 | C4: ='Work Steps'!F3 -> Trim | D4: ='Work Steps'!G3 -> Cut Velcro | E4: =INDEX(Analysis!$S$5:$Y$35,MATCH('Prod Plan 0115'!$A4,Analysis!$S$5:$S$35,0),4) -> 0 | G4: =INDEX(Analysis!$S$5:$Y$35,MATCH('Prod Plan 0115'!$A4,Analysis!$S$5:$S$35,0),7) -> 0 | L4: =IF(E4=0,0,400-E4+K4) -> 0 | M4: =E4-K4 -> 0 | O4: =M4/INDEX(Analysis!$S$5:$Y$35,MATCH('Prod Plan 0115'!$A4,Analysis!$S$5:$S$35,0),3) -> 0 | T4: =IF(M4=0,0,400-M4+S4) -> 0 | U4: =M4-S4 -> 0 | W4: =U4/INDEX(Analysis!$S$5:$Y$35,MATCH('Prod Plan 0115'!$A4,Analysis!$S$5:$S$35,0),3) -> 0 | AB4: =IF(U4=0,0,400-U4+AA4) -> 0
A5: ='Work Steps'!C4 -> PSA1 | B5: ='Work Steps'!D4 -> 3 | C5: ='Work Steps'!F4 -> Fabric | D5: ='Work Steps'!G4 -> Sew flag on panel | E5: =INDEX(Analysis!$S$5:$Y$35,MATCH('Prod Plan 0115'!$A5,Analysis!$S$5:$S$35,0),4) -> 0 | G5: =INDEX(Analysis!$S$5:$Y$35,MATCH('Prod Plan 0115'!$A5,Analysis!$S$5:$S$35,0),7) -> 0 | L5: =IF(E5=0,0,400-E5+K5) -> 0 | M5: =E5-K5 -> 0 | O5: =M5/INDEX(Analysis!$S$5:$Y$35,MATCH('Prod Plan 0115'!$A5,Analysis!$S$5:$S$35,0),3) -> 0 | T5: =IF(M5=0,0,400-M5+S5) -> 0 | U5: =M5-S5 -> 0 | W5: =U5/INDEX(Analysis!$S$5:$Y$35,MATCH('Prod Plan 0115'!$A5,Analysis!$S$5:$S$35,0),3) -> 0 | AB5: =IF(U5=0,0,400-U5+AA5) -> 0
A6: ='Work Steps'!C5 -> SA1 | B6: ='Work Steps'!D5 -> 4 | C6: ='Work Steps'!F5 -> A1. Small Velcro Pocket | D6: ='Work Steps'!G5 -> Hem short edge | E6: =INDEX(Analysis!$S$5:$Y$35,MATCH('Prod Plan 0115'!$A6,Analysis!$S$5:$S$35,0),4) -> 200 | F6: Oralia R. | G6: =INDEX(Analysis!$S$5:$Y$35,MATCH('Prod Plan 0115'!$A6,Analysis!$S$5:$S$35,0),7) -> 2.8145695 | H6: 1 | I6: 0.25 | J6: =IF((I6+(G6/H6)/24)+(0.5/24)>0.6875,0.6875,(I6+(G6/H6)/24)+(0.5/24)) -> 0.38810706 | K6: =IF((((J6-I6)*24)*H6)*INDEX(Analysis!$S$5:$Y$35,MATCH('Prod Plan 0115'!$A6,Analysis!$S$5:$S$35,0),3)>E6,E6,(((J6-I6)*24)*H6)*INDEX(Analysis!$S$5:$Y$35,MATCH('Prod Plan 0115'!$A6,Analysis!$S$5:$S$35,0),3)) -> 200 | L6: =IF(E6=0,0,400-E6+K6) -> 400 | M6: =E6-K6 -> 0 | O6: =M6/INDEX(Analysis!$S$5:$Y$35,MATCH('Prod Plan 0115'!$A6,Analysis!$S$5:$S$35,0),3) -> 0 | T6: =IF(M6=0,0,400-M6+S6) -> 0 | U6: =M6-S6 -> 0 | W6: =U6/INDEX(Analysis!$S$5:$Y$35,MATCH('Prod Plan 0115'!$A6,Analysis!$S$5:$S$35,0),3) -> 0 | AB6: =IF(U6=0,0,400-U6+AA6) -> 0
A7: ='Work Steps'!C6 -> SA2 | B7: ='Work Steps'!D6 -> 5 | C7: ='Work Steps'!F6 -> A2. Small Velcro Pocket | D7: ='Work Steps'!G6 -> Sew hook velcro | E7: =INDEX(Analysis!$S$5:$Y$35,MATCH('Prod Plan 0115'!$A7,Analysis!$S$5:$S$35,0),4) -> 400 | F7: Jackie | G7: =INDEX(Analysis!$S$5:$Y$35,MATCH('Prod Plan 0115'!$A7,Analysis!$S$5:$S$35,0),7) -> 10.457516 | H7: 1 | I7: 0.25 | J7: =IF((I7+(G7/H7)/24)+(0.5/24)>0.6875,0.6875,(I7+(G7/H7)/24)+(0.5/24)) -> 0.6875 | K7: =IF((((J7-I7)*24)*H7)*INDEX(Analysis!$S$5:$Y$35,MATCH('Prod Plan 0115'!$A7,Analysis!$S$5:$S$35,0),3)>E7,E7,(((J7-I7)*24)*H7)*INDEX(Analysis!$S$5:$Y$35,MATCH('Prod Plan 0115'!$A7,Analysis!$S$5:$S$35,0),3)) -> 400 | L7: =IF(E7=0,0,400-E7+K7) -> 400 | M7: =E7-K7 -> 0 | O7: =M7/INDEX(Analysis!$S$5:$Y$35,MATCH('Prod Plan 0115'!$A7,Analysis!$S$5:$S$35,0),3) -> 0 | T7: =IF(M7=0,0,400-M7+S7) -> 0 | U7: =M7-S7 -> 0 | W7: =U7/INDEX(Analysis!$S$5:$Y$35,MATCH('Prod Plan 0115'!$A7,Analysis!$S$5:$S$35,0),3) -> 0 | AB7: =IF(U7=0,0,400-U7+AA7) -> 0
A8: ='Work Steps'!C7 -> SB1 | B8: ='Work Steps'!D7 -> 6 | C8: ='Work Steps'!F7 -> B1. Connector Strap | D8: ='Work Steps'!G7 -> Sew the panel together along the long sides | E8: =INDEX(Analysis!$S$5:$Y$35,MATCH('Prod Plan 0115'!$A8,Analysis!$S$5:$S$35,0),4) -> 0 | G8: =INDEX(Analysis!$S$5:$Y$35,MATCH('Prod Plan 0115'!$A8,Analysis!$S$5:$S$35,0),7) -> 0 | L8: =IF(E8=0,0,400-E8+K8) -> 0 | M8: =E8-K8 -> 0 | O8: =M8/INDEX(Analysis!$S$5:$Y$35,MATCH('Prod Plan 0115'!$A8,Analysis!$S$5:$S$35,0),3) -> 0 | T8: =IF(M8=0,0,400-M8+S8) -> 0 | U8: =M8-S8 -> 0 | W8: =U8/INDEX(Analysis!$S$5:$Y$35,MATCH('Prod Plan 0115'!$A8,Analysis!$S$5:$S$35,0),3) -> 0 | AB8: =IF(U8=0,0,400-U8+AA8) -> 0
A9: ='Work Steps'!C8 -> SB2 | B9: ='Work Steps'!D8 -> 7 | C9: ='Work Steps'!F8 -> B2. Connector Strap | D9: ='Work Steps'!G8 -> Turn inside out | E9: =INDEX(Analysis!$S$5:$Y$35,MATCH('Prod Plan 0115'!$A9,Analysis!$S$5:$S$35,0),4) -> 0 | G9: =INDEX(Analysis!$S$5:$Y$35,MATCH('Prod Plan 0115'!$A9,Analysis!$S$5:$S$35,0),7) -> 0 | L9: =IF(E9=0,0,400-E9+K9) -> 0 | M9: =E9-K9 -> 0 | O9: =M9/INDEX(Analysis!$S$5:$Y$35,MATCH('Prod Plan 0115'!$A9,Analysis!$S$5:$S$35,0),3) -> 0 | T9: =IF(M9=0,0,400-M9+S9) -> 0 | U9: =M9-S9 -> 0 | W9: =U9/INDEX(Analysis!$S$5:$Y$35,MATCH('Prod Plan 0115'!$A9,Analysis!$S$5:$S$35,0),3) -> 0 | AB9: =IF(U9=0,0,400-U9+AA9) -> 0
A10: ='Work Steps'!C9 -> SB3 | B10: ='Work Steps'!D9 -> 8 | C10: ='Work Steps'!F9 -> B3. Connector Strap | D10: ='Work Steps'!G9 -> Sew the 2 long sides of the connector Strap panel | E10: =INDEX(Analysis!$S$5:$Y$35,MATCH('Prod Plan 0115'!$A10,Analysis!$S$5:$S$35,0),4) -> 18 | F10: Oralia S. | G10: =INDEX(Analysis!$S$5:$Y$35,MATCH('Prod Plan 0115'!$A10,Analysis!$S$5:$S$35,0),7) -> 0.28548964 | H10: 1 | I10: 0.25 | J10: =IF((I10+(G10/H10)/24)+(0.5/24)>0.6875,0.6875,(I10+(G10/H10)/24)+(0.5/24)) -> 0.28272874 | K10: =IF((((J10-I10)*24)*H10)*INDEX(Analysis!$S$5:$Y$35,MATCH('Prod Plan 0115'!$A10,Analysis!$S$5:$S$35,0),3)>E10,E10,(((J10-I10)*24)*H10)*INDEX(Analysis!$S$5:$Y$35,MATCH('Prod Plan 0115'!$A10,Analysis!$S$5:$S$35,0),3)) -> 18 | L10: =IF(E10=0,0,400-E10+K10) -> 400 | M10: =E10-K10 -> 0 | O10: =M10/INDEX(Analysis!$S$5:$Y$35,MATCH('Prod Plan 0115'!$A10,Analysis!$S$5:$S$35,0),3) -> 0 | T10: =IF(M10=0,0,400-M10+S10) -> 0 | U10: =M10-S10 -> 0 | W10: =U10/INDEX(Analysis!$S$5:$Y$35,MATCH('Prod Plan 0115'!$A10,Analysis!$S$5:$S$35,0),3) -> 0 | AB10: =IF(U10=0,0,400-U10+AA10) -> 0
A11: ='Work Steps'!C10 -> SB4 | B11: ='Work Steps'!D10 -> 9 | C11: ='Work Steps'!F10 -> B4. Connector Strap | D11: ='Work Steps'!G10 -> Sew the connector strap to the small Velcro pocket, add the loop Velcro. | E11: =INDEX(Analysis!$S$5:$Y$35,MATCH('Prod Plan 0115'!$A11,Analysis!$S$5:$S$35,0),4) -> 400 | F11: Maricela | G11: =INDEX(Analysis!$S$5:$Y$35,MATCH('Prod Plan 0115'!$A11,Analysis!$S$5:$S$35,0),7) -> 7.8762307 | H11: 1 | I11: 0.25 | J11: =IF((I11+(G11/H11)/24)+(0.5/24)>0.6875,0.6875,(I11+(G11/H11)/24)+(0.5/24)) -> 0.59900961 | K11: =IF((((J11-I11)*24)*H11)*INDEX(Analysis!$S$5:$Y$35,MATCH('Prod Plan 0115'!$A11,Analysis!$S$5:$S$35,0),3)>E11,E11,(((J11-I11)*24)*H11)*INDEX(Analysis!$S$5:$Y$35,MATCH('Prod Plan 0115'!$A11,Analysis!$S$5:$S$35,0),3)) -> 400 | L11: =IF(E11=0,0,400-E11+K11) -> 400 | M11: =E11-K11 -> 0 | O11: =M11/INDEX(Analysis!$S$5:$Y$35,MATCH('Prod Plan 0115'!$A11,Analysis!$S$5:$S$35,0),3) -> 0 | T11: =IF(M11=0,0,400-M11+S11) -> 0 | U11: =M11-S11 -> 0 | W11: =U11/INDEX(Analysis!$S$5:$Y$35,MATCH('Prod Plan 0115'!$A11,Analysis!$S$5:$S$35,0),3) -> 0 | AB11: =IF(U11=0,0,400-U11+AA11) -> 0
A12: ='Work Steps'!C11 -> SB5 | B12: ='Work Steps'!D11 -> 10 | C12: ='Work Steps'!F11 -> B5. Connector Strap | D12: ='Work Steps'!G11 -> Close the sides of the small Velcro pocket. | E12: =INDEX(Analysis!$S$5:$Y$35,MATCH('Prod Plan 0115'!$A12,Analysis!$S$5:$S$35,0),4) -> 400 | F12: Maricela, Cindy | G12: =INDEX(Analysis!$S$5:$Y$35,MATCH('Prod Plan 0115'!$A12,Analysis!$S$5:$S$35,0),7) -> 8.520956 | H12: 2 | I12: =J11+((5/60)/24) -> 0.60248183 | J12: =IF((I12+(G12/H12)/24)+(0.5/24)>0.6875,0.6875,(I12+(G12/H12)/24)+(0.5/24)) -> 0.6875 | K12: =IF((((J12-I12)*24)*H12)*INDEX(Analysis!$S$5:$Y$35,MATCH('Prod Plan 0115'!$A12,Analysis!$S$5:$S$35,0),3)>E12,E12,(((J12-I12)*24)*H12)*INDEX(Analysis!$S$5:$Y$35,MATCH('Prod Plan 0115'!$A12,Analysis!$S$5:$S$35,0),3)) -> 191.56874 | L12: =IF(E12=0,0,400-E12+K12) -> 191.56874 | M12: =E12-K12 -> 208.43126 | N12: Maricela | O12: =M12/INDEX(Analysis!$S$5:$Y$35,MATCH('Prod Plan 0115'!$A12,Analysis!$S$5:$S$35,0),3) -> 4.440084 | P12: 1 | Q12: 0.25 | R12: =IF((Q12+(O12/P12)/24)+(0.5/24)>0.6875,0.6875,(Q12+(O12/P12)/24)+(0.5/24)) -> 0.45583683 | S12: =IF((((R12-Q12)*24)*P12)*INDEX(Analysis!$S$5:$Y$35,MATCH('Prod Plan 0115'!$A12,Analysis!$S$5:$S$35,0),3)>M12,M12,(((R12-Q12)*24)*P12)*INDEX(Analysis!$S$5:$Y$35,MATCH('Prod Plan 0115'!$A12,Analysis!$S$5:$S$35,0),3)) -> 208.43126 | T12: =IF(M12=0,0,400-M12+S12) -> 400 | U12: =M12-S12 -> 0 | W12: =U12/INDEX(Analysis!$S$5:$Y$35,MATCH('Prod Plan 0115'!$A12,Analysis!$S$5:$S$35,0),3) -> 0 | AB12: =IF(U12=0,0,400-U12+AA12) -> 0
A13: ='Work Steps'!C12 -> SB6 | B13: ='Work Steps'!D12 -> 11 | C13: ='Work Steps'!F12 -> B6. Connector Strap | D13: ='Work Steps'!G12 -> Cut threads, Turn right side out, Cut corners | E13: =INDEX(Analysis!$S$5:$Y$35,MATCH('Prod Plan 0115'!$A13,Analysis!$S$5:$S$35,0),4) -> 400 | F13: Patty, Noe | G13: =INDEX(Analysis!$S$5:$Y$35,MATCH('Prod Plan 0115'!$A13,Analysis!$S$5:$S$35,0),7) -> 8.3076923 | H13: 2 | I13: 0.60416667 | J13: =IF((I13+(G13/H13)/24)+(0.5/24)>0.6875,0.6875,(I13+(G13/H13)/24)+(0.5/24)) -> 0.6875 | K13: =IF((((J13-I13)*24)*H13)*INDEX(Analysis!$S$5:$Y$35,MATCH('Prod Plan 0115'!$A13,Analysis!$S$5:$S$35,0),3)>E13,E13,(((J13-I13)*24)*H13)*INDEX(Analysis!$S$5:$Y$35,MATCH('Prod Plan 0115'!$A13,Analysis!$S$5:$S$35,0),3)) -> 192.59259 | L13: =IF(E13=0,0,400-E13+K13) -> 192.59259 | M13: =E13-K13 -> 207.40741 | N13: Patty | O13: =M13/INDEX(Analysis!$S$5:$Y$35,MATCH('Prod Plan 0115'!$A13,Analysis!$S$5:$S$35,0),3) -> 4.3076923 | P13: 1 | Q13: 0.25 | R13: =IF((Q13+(O13/P13)/24)+(0.5/24)>0.6875,0.6875,(Q13+(O13/P13)/24)+(0.5/24)) -> 0.45032051 | S13: =IF((((R13-Q13)*24)*P13)*INDEX(Analysis!$S$5:$Y$35,MATCH('Prod Plan 0115'!$A13,Analysis!$S$5:$S$35,0),3)>M13,M13,(((R13-Q13)*24)*P13)*INDEX(Analysis!$S$5:$Y$35,MATCH('Prod Plan 0115'!$A13,Analysis!$S$5:$S$35,0),3)) -> 207.40741 | T13: =IF(M13=0,0,400-M13+S13) -> 400 | U13: =M13-S13 -> 0 | W13: =U13/INDEX(Analysis!$S$5:$Y$35,MATCH('Prod Plan 0115'!$A13,Analysis!$S$5:$S$35,0),3) -> 0 | AB13: =IF(U13=0,0,400-U13+AA13) -> 0
A14: ='Work Steps'!C13 -> SC1 | B14: ='Work Steps'!D13 -> 12 | C14: ='Work Steps'!F13 -> C1. Hanging Big Pocket | D14: ='Work Steps'!G13 -> Hem one short side | E14: =INDEX(Analysis!$S$5:$Y$35,MATCH('Prod Plan 0115'!$A14,Analysis!$S$5:$S$35,0),4) -> 400 | F14: Oralia S. | G14: =INDEX(Analysis!$S$5:$Y$35,MATCH('Prod Plan 0115'!$A14,Analysis!$S$5:$S$35,0),7) -> 3.4850088 | H14: 1 | I14: =J10+((5/60)/24) -> 0.28620096 | J14: =IF((I14+(G14/H14)/24)+(0.5/24)>0.6875,0.6875,(I14+(G14/H14)/24)+(0.5/24)) -> 0.45224299 | K14: =IF((((J14-I14)*24)*H14)*INDEX(Analysis!$S$5:$Y$35,MATCH('Prod Plan 0115'!$A14,Analysis!$S$5:$S$35,0),3)>E14,E14,(((J14-I14)*24)*H14)*INDEX(Analysis!$S$5:$Y$35,MATCH('Prod Plan 0115'!$A14,Analysis!$S$5:$S$35,0),3)) -> 400 | L14: =IF(E14=0,0,400-E14+K14) -> 400 | M14: =E14-K14 -> 0 | O14: =M14/INDEX(Analysis!$S$5:$Y$35,MATCH('Prod Plan 0115'!$A14,Analysis!$S$5:$S$35,0),3) -> 0 | T14: =IF(M14=0,0,400-M14+S14) -> 0 | U14: =M14-S14 -> 0 | W14: =U14/INDEX(Analysis!$S$5:$Y$35,MATCH('Prod Plan 0115'!$A14,Analysis!$S$5:$S$35,0),3) -> 0 | AB14: =IF(U14=0,0,400-U14+AA14) -> 0
A15: ='Work Steps'!C14 -> SC2 | B15: ='Work Steps'!D14 -> 13 | C15: ='Work Steps'!F14 -> C2. Hanging Big Pocket | D15: ='Work Steps'!G14 -> Fold to the marking, and close both sides | E15: =INDEX(Analysis!$S$5:$Y$35,MATCH('Prod Plan 0115'!$A15,Analysis!$S$5:$S$35,0),4) -> 400 | F15: Oralia R., Oralia S. | G15: =INDEX(Analysis!$S$5:$Y$35,MATCH('Prod Plan 0115'!$A15,Analysis!$S$5:$S$35,0),7) -> 5.6648778 | H15: 2 | I15: 0.4375 | J15: =IF((I15+(G15/H15)/24)+(0.5/24)>0.6875,0.6875,(I15+(G15/H15)/24)+(0.5/24)) -> 0.57635162 | K15: =IF((((J15-I15)*24)*H15)*INDEX(Analysis!$S$5:$Y$35,MATCH('Prod Plan 0115'!$A15,Analysis!$S$5:$S$35,0),3)>E15,E15,(((J15-I15)*24)*H15)*INDEX(Analysis!$S$5:$Y$35,MATCH('Prod Plan 0115'!$A15,Analysis!$S$5:$S$35,0),3)) -> 400 | L15: =IF(E15=0,0,400-E15+K15) -> 400 | M15: =E15-K15 -> 0 | O15: =M15/INDEX(Analysis!$S$5:$Y$35,MATCH('Prod Plan 0115'!$A15,Analysis!$S$5:$S$35,0),3) -> 0 | T15: =IF(M15=0,0,400-M15+S15) -> 0 | U15: =M15-S15 -> 0 | W15: =U15/INDEX(Analysis!$S$5:$Y$35,MATCH('Prod Plan 0115'!$A15,Analysis!$S$5:$S$35,0),3) -> 0 | AB15: =IF(U15=0,0,400-U15+AA15) -> 0
A16: ='Work Steps'!C15 -> SC3 | B16: ='Work Steps'!D15 -> 14 | C16: ='Work Steps'!F15 -> C3. Hanging Big Pocket | D16: ='Work Steps'!G15 -> Add stitching to the lower corners to create volume | E16: =INDEX(Analysis!$S$5:$Y$35,MATCH('Prod Plan 0115'!$A16,Analysis!$S$5:$S$35,0),4) -> 400 | F16: Oralia R., Oralia S. | G16: =INDEX(Analysis!$S$5:$Y$35,MATCH('Prod Plan 0115'!$A16,Analysis!$S$5:$S$35,0),7) -> 4.4759494 | H16: 2 | I16: =J22+((5/60)/24) -> 0.59850342 | J16: =IF((I16+(G16/H16)/24)+(0.5/24)>0.6875,0.6875,(I16+(G16/H16)/24)+(0.5/24)) -> 0.6875 | K16: =IF((((J16-I16)*24)*H16)*INDEX(Analysis!$S$5:$Y$35,MATCH('Prod Plan 0115'!$A16,Analysis!$S$5:$S$35,0),3)>E16,E16,(((J16-I16)*24)*H16)*INDEX(Analysis!$S$5:$Y$35,MATCH('Prod Plan 0115'!$A16,Analysis!$S$5:$S$35,0),3)) -> 381.7591 | L16: =IF(E16=0,0,400-E16+K16) -> 381.7591 | M16: =E16-K16 -> 18.2409 | N16: Oralia S. | O16: =M16/INDEX(Analysis!$S$5:$Y$35,MATCH('Prod Plan 0115'!$A16,Analysis!$S$5:$S$35,0),3) -> 0.20411336 | P16: 1 | Q16: 0.25 | R16: =IF((Q16+(O16/P16)/24)+(0.5/24)>0.6875,0.6875,(Q16+(O16/P16)/24)+(0.5/24)) -> 0.27933806 | S16: =IF((((R16-Q16)*24)*P16)*INDEX(Analysis!$S$5:$Y$35,MATCH('Prod Plan 0115'!$A16,Analysis!$S$5:$S$35,0),3)>M16,M16,(((R16-Q16)*24)*P16)*INDEX(Analysis!$S$5:$Y$35,MATCH('Prod Plan 0115'!$A16,Analysis!$S$5:$S$35,0),3)) -> 18.2409 | T16: =IF(M16=0,0,400-M16+S16) -> 400 | U16: =M16-S16 -> 0 | W16: =U16/INDEX(Analysis!$S$5:$Y$35,MATCH('Prod Plan 0115'!$A16,Analysis!$S$5:$S$35,0),3) -> 0 | AB16: =IF(U16=0,0,400-U16+AA16) -> 0
A17: ='Work Steps'!C16 -> SC4 | B17: ='Work Steps'!D16 -> 15 | C17: ='Work Steps'!F16 -> C4. Hanging Big Pocket | D17: ='Work Steps'!G16 -> Turn right side out | E17: =INDEX(Analysis!$S$5:$Y$35,MATCH('Prod Plan 0115'!$A17,Analysis!$S$5:$S$35,0),4) -> 400 | F17: Pilar, Obet | G17: =INDEX(Analysis!$S$5:$Y$35,MATCH('Prod Plan 0115'!$A17,Analysis!$S$5:$S$35,0),7) -> 5.9952038 | H17: 2 | I17: 0.59722222 | J17: =IF((I17+(G17/H17)/24)+(0.5/24)>0.6875,0.6875,(I17+(G17/H17)/24)+(0.5/24)) -> 0.6875 | K17: =IF((((J17-I17)*24)*H17)*INDEX(Analysis!$S$5:$Y$35,MATCH('Prod Plan 0115'!$A17,Analysis!$S$5:$S$35,0),3)>E17,E17,(((J17-I17)*24)*H17)*INDEX(Analysis!$S$5:$Y$35,MATCH('Prod Plan 0115'!$A17,Analysis!$S$5:$S$35,0),3)) -> 289.12 | L17: =IF(E17=0,0,400-E17+K17) -> 289.12 | M17: =E17-K17 -> 110.88 | N17: Pilar | O17: =M17/INDEX(Analysis!$S$5:$Y$35,MATCH('Prod Plan 0115'!$A17,Analysis!$S$5:$S$35,0),3) -> 1.6618705 | P17: 1 | Q17: 0.25 | R17: =IF((Q17+(O17/P17)/24)+(0.5/24)>0.6875,0.6875,(Q17+(O17/P17)/24)+(0.5/24)) -> 0.34007794 | S17: =IF((((R17-Q17)*24)*P17)*INDEX(Analysis!$S$5:$Y$35,MATCH('Prod Plan 0115'!$A17,Analysis!$S$5:$S$35,0),3)>M17,M17,(((R17-Q17)*24)*P17)*INDEX(Analysis!$S$5:$Y$35,MATCH('Prod Plan 0115'!$A17,Analysis!$S$5:$S$35,0),3)) -> 110.88 | T17: =IF(M17=0,0,400-M17+S17) -> 400 | U17: =M17-S17 -> 0 | W17: =U17/INDEX(Analysis!$S$5:$Y$35,MATCH('Prod Plan 0115'!$A17,Analysis!$S$5:$S$35,0),3) -> 0 | AB17: =IF(U17=0,0,400-U17+AA17) -> 0
A18: ='Work Steps'!C17 -> SC5 | B18: ='Work Steps'!D17 -> 16 | C18: ='Work Steps'!F17 -> C5. Hanging Big Pocket | D18: ='Work Steps'!G17 -> Add straight single-stitching to the top of the pocket | E18: =INDEX(Analysis!$S$5:$Y$35,MATCH('Prod Plan 0115'!$A18,Analysis!$S$5:$S$35,0),4) -> 400 | G18: =INDEX(Analysis!$S$5:$Y$35,MATCH('Prod Plan 0115'!$A18,Analysis!$S$5:$S$35,0),7) -> 5.2743602 | L18: =IF(E18=0,0,400-E18+K18) -> 0 | M18: =E18-K18 -> 400 | N18: Angelica, Oralia R | O18: =M18/INDEX(Analysis!$S$5:$Y$35,MATCH('Prod Plan 0115'!$A18,Analysis!$S$5:$S$35,0),3) -> 5.2743602 | P18: 2 | Q18: 0.25 | R18: =IF((Q18+(O18/P18)/24)+(0.5/24)>0.6875,0.6875,(Q18+(O18/P18)/24)+(0.5/24)) -> 0.38071584 | S18: =IF((((R18-Q18)*24)*P18)*INDEX(Analysis!$S$5:$Y$35,MATCH('Prod Plan 0115'!$A18,Analysis!$S$5:$S$35,0),3)>M18,M18,(((R18-Q18)*24)*P18)*INDEX(Analysis!$S$5:$Y$35,MATCH('Prod Plan 0115'!$A18,Analysis!$S$5:$S$35,0),3)) -> 400 | T18: =IF(M18=0,0,400-M18+S18) -> 400 | U18: =M18-S18 -> 0 | W18: =U18/INDEX(Analysis!$S$5:$Y$35,MATCH('Prod Plan 0115'!$A18,Analysis!$S$5:$S$35,0),3) -> 0 | AB18: =IF(U18=0,0,400-U18+AA18) -> 0
A19: ='Work Steps'!C18 -> SC6 | B19: ='Work Steps'!D18 -> 17 | C19: ='Work Steps'!F18 -> C6. Hanging Big Pocket | D19: ='Work Steps'!G18 -> Sew the center stitch | E19: =INDEX(Analysis!$S$5:$Y$35,MATCH('Prod Plan 0115'!$A19,Analysis!$S$5:$S$35,0),4) -> 400 | G19: =INDEX(Analysis!$S$5:$Y$35,MATCH('Prod Plan 0115'!$A19,Analysis!$S$5:$S$35,0),7) -> 6.8292683 | L19: =IF(E19=0,0,400-E19+K19) -> 0 | M19: =E19-K19 -> 400 | N19: All | O19: =M19/INDEX(Analysis!$S$5:$Y$35,MATCH('Prod Plan 0115'!$A19,Analysis!$S$5:$S$35,0),3) -> 6.8292683 | P19: 6 | Q19: =R18+((5/60)/24) -> 0.38418806 | R19: =IF((Q19+(O19/P19)/24)+(0.5/24)>0.6875,0.6875,(Q19+(O19/P19)/24)+(0.5/24)) -> 0.45244687 | S19: =IF((((R19-Q19)*24)*P19)*INDEX(Analysis!$S$5:$Y$35,MATCH('Prod Plan 0115'!$A19,Analysis!$S$5:$S$35,0),3)>M19,M19,(((R19-Q19)*24)*P19)*INDEX(Analysis!$S$5:$Y$35,MATCH('Prod Plan 0115'!$A19,Analysis!$S$5:$S$35,0),3)) -> 400 | T19: =IF(M19=0,0,400-M19+S19) -> 400 | U19: =M19-S19 -> 0 | W19: =U19/INDEX(Analysis!$S$5:$Y$35,MATCH('Prod Plan 0115'!$A19,Analysis!$S$5:$S$35,0),3) -> 0 | AB19: =IF(U19=0,0,400-U19+AA19) -> 0
A20: ='Work Steps'!C19 -> SC7 | B20: ='Work Steps'!D19 -> 18 | C20: ='Work Steps'!F19 -> C7. Bartack | D20: ='Work Steps'!G19 -> Add the bartack to the top of the hanging big pocket | E20: =INDEX(Analysis!$S$5:$Y$35,MATCH('Prod Plan 0115'!$A20,Analysis!$S$5:$S$35,0),4) -> 400 | G20: =INDEX(Analysis!$S$5:$Y$35,MATCH('Prod Plan 0115'!$A20,Analysis!$S$5:$S$35,0),7) -> 3.9106145 | L20: =IF(E20=0,0,400-E20+K20) -> 0 | M20: =E20-K20 -> 400 | N20: All | O20: =M20/INDEX(Analysis!$S$5:$Y$35,MATCH('Prod Plan 0115'!$A20,Analysis!$S$5:$S$35,0),3) -> 3.9106145 | P20: 6 | Q20: =R19+((5/60)/24) -> 0.45591909 | R20: =IF((Q20+(O20/P20)/24)+(0.5/24)>0.6875,0.6875,(Q20+(O20/P20)/24)+(0.5/24)) -> 0.50390947 | S20: =IF((((R20-Q20)*24)*P20)*INDEX(Analysis!$S$5:$Y$35,MATCH('Prod Plan 0115'!$A20,Analysis!$S$5:$S$35,0),3)>M20,M20,(((R20-Q20)*24)*P20)*INDEX(Analysis!$S$5:$Y$35,MATCH('Prod Plan 0115'!$A20,Analysis!$S$5:$S$35,0),3)) -> 400 | T20: =IF(M20=0,0,400-M20+S20) -> 400 | U20: =M20-S20 -> 0 | W20: =U20/INDEX(Analysis!$S$5:$Y$35,MATCH('Prod Plan 0115'!$A20,Analysis!$S$5:$S$35,0),3) -> 0 | AB20: =IF(U20=0,0,400-U20+AA20) -> 0
A21: ='Work Steps'!C20 -> SC8 | B21: ='Work Steps'!D20 -> 19 | C21: ='Work Steps'!F20 -> C8. Hanging Big Pocket | D21: ='Work Steps'!G20 -> Stitch the connector strap to the large pocket | E21: =INDEX(Analysis!$S$5:$Y$35,MATCH('Prod Plan 0115'!$A21,Analysis!$S$5:$S$35,0),4) -> 400 | G21: =INDEX(Analysis!$S$5:$Y$35,MATCH('Prod Plan 0115'!$A21,Analysis!$S$5:$S$35,0),7) -> 4.9311439 | L21: =IF(E21=0,0,400-E21+K21) -> 0 | M21: =E21-K21 -> 400 | N21: All | O21: =M21/INDEX(Analysis!$S$5:$Y$35,MATCH('Prod Plan 0115'!$A21,Analysis!$S$5:$S$35,0),3) -> 4.9311439 | P21: 6 | Q21: =R20+((5/60)/24) -> 0.50738169 | R21: =IF((Q21+(O21/P21)/24)+(0.5/24)>0.6875,0.6875,(Q21+(O21/P21)/24)+(0.5/24)) -> 0.56245908 | S21: =IF((((R21-Q21)*24)*P21)*INDEX(Analysis!$S$5:$Y$35,MATCH('Prod Plan 0115'!$A21,Analysis!$S$5:$S$35,0),3)>M21,M21,(((R21-Q21)*24)*P21)*INDEX(Analysis!$S$5:$Y$35,MATCH('Prod Plan 0115'!$A21,Analysis!$S$5:$S$35,0),3)) -> 400 | T21: =IF(M21=0,0,400-M21+S21) -> 400 | U21: =M21-S21 -> 0 | W21: =U21/INDEX(Analysis!$S$5:$Y$35,MATCH('Prod Plan 0115'!$A21,Analysis!$S$5:$S$35,0),3) -> 0 | AB21: =IF(U21=0,0,400-U21+AA21) -> 0
A22: ='Work Steps'!C21 -> SD1 | B22: ='Work Steps'!D21 -> 20 | C22: ='Work Steps'!F21 -> D1. Cushion Cover | D22: ='Work Steps'!G21 -> Sew the zipper onto the left panel with USA flag. | E22: =INDEX(Analysis!$S$5:$Y$35,MATCH('Prod Plan 0115'!$A22,Analysis!$S$5:$S$35,0),4) -> 300 | F22: Cindy | G22: =INDEX(Analysis!$S$5:$Y$35,MATCH('Prod Plan 0115'!$A22,Analysis!$S$5:$S$35,0),7) -> 7.7807487 | H22: 1 | I22: 0.25 | J22: =IF((I22+(G22/H22)/24)+(0.5/24)>0.6875,0.6875,(I22+(G22/H22)/24)+(0.5/24)) -> 0.59503119 | K22: =IF((((J22-I22)*24)*H22)*INDEX(Analysis!$S$5:$Y$35,MATCH('Prod Plan 0115'!$A22,Analysis!$S$5:$S$35,0),3)>E22,E22,(((J22-I22)*24)*H22)*INDEX(Analysis!$S$5:$Y$35,MATCH('Prod Plan 0115'!$A22,Analysis!$S$5:$S$35,0),3)) -> 300 | L22: =IF(E22=0,0,400-E22+K22) -> 400 | M22: =E22-K22 -> 0 | O22: =M22/INDEX(Analysis!$S$5:$Y$35,MATCH('Prod Plan 0115'!$A22,Analysis!$S$5:$S$35,0),3) -> 0 | T22: =IF(M22=0,0,400-M22+S22) -> 0 | U22: =M22-S22 -> 0 | W22: =U22/INDEX(Analysis!$S$5:$Y$35,MATCH('Prod Plan 0115'!$A22,Analysis!$S$5:$S$35,0),3) -> 0 | AB22: =IF(U22=0,0,400-U22+AA22) -> 0
A23: ='Work Steps'!C22 -> SD2 | B23: ='Work Steps'!D22 -> 21 | C23: ='Work Steps'!F22 -> D2. Cushion Cover | D23: ='Work Steps'!G22 -> Sew the zipper with hemming foot onto the right panel without the flag | E23: =INDEX(Analysis!$S$5:$Y$35,MATCH('Prod Plan 0115'!$A23,Analysis!$S$5:$S$35,0),4) -> 0 | G23: =INDEX(Analysis!$S$5:$Y$35,MATCH('Prod Plan 0115'!$A23,Analysis!$S$5:$S$35,0),7) -> 0 | L23: =IF(E23=0,0,400-E23+K23) -> 0 | M23: =E23-K23 -> 0 | O23: =M23/INDEX(Analysis!$S$5:$Y$35,MATCH('Prod Plan 0115'!$A23,Analysis!$S$5:$S$35,0),3) -> 0 | T23: =IF(M23=0,0,400-M23+S23) -> 0 | U23: =M23-S23 -> 0 | W23: =U23/INDEX(Analysis!$S$5:$Y$35,MATCH('Prod Plan 0115'!$A23,Analysis!$S$5:$S$35,0),3) -> 0 | AB23: =IF(U23=0,0,400-U23+AA23) -> 0
A24: ='Work Steps'!C23 -> SD3 | B24: ='Work Steps'!D23 -> 22 | C24: ='Work Steps'!F23 -> D3. Cushion Cover | D24: ='Work Steps'!G23 -> Cut extra material off add the zipper pull | E24: =INDEX(Analysis!$S$5:$Y$35,MATCH('Prod Plan 0115'!$A24,Analysis!$S$5:$S$35,0),4) -> 400 | F24: Julieta | G24: =INDEX(Analysis!$S$5:$Y$35,MATCH('Prod Plan 0115'!$A24,Analysis!$S$5:$S$35,0),7) -> 15.646259 | H24: 1 | I24: 0.25 | J24: =IF((I24+(G24/H24)/24)+(0.5/24)>0.6875,0.6875,(I24+(G24/H24)/24)+(0.5/24)) -> 0.6875 | K24: =IF((((J24-I24)*24)*H24)*INDEX(Analysis!$S$5:$Y$35,MATCH('Prod Plan 0115'!$A24,Analysis!$S$5:$S$35,0),3)>E24,E24,(((J24-I24)*24)*H24)*INDEX(Analysis!$S$5:$Y$35,MATCH('Prod Plan 0115'!$A24,Analysis!$S$5:$S$35,0),3)) -> 268.43478 | L24: =IF(E24=0,0,400-E24+K24) -> 268.43478 | M24: =E24-K24 -> 131.56522 | N24: Julieta, Obet | O24: =M24/INDEX(Analysis!$S$5:$Y$35,MATCH('Prod Plan 0115'!$A24,Analysis!$S$5:$S$35,0),3) -> 5.1462585 | P24: 2 | Q24: 0.25 | R24: =IF((Q24+(O24/P24)/24)+(0.5/24)>0.6875,0.6875,(Q24+(O24/P24)/24)+(0.5/24)) -> 0.37804705 | S24: =IF((((R24-Q24)*24)*P24)*INDEX(Analysis!$S$5:$Y$35,MATCH('Prod Plan 0115'!$A24,Analysis!$S$5:$S$35,0),3)>M24,M24,(((R24-Q24)*24)*P24)*INDEX(Analysis!$S$5:$Y$35,MATCH('Prod Plan 0115'!$A24,Analysis!$S$5:$S$35,0),3)) -> 131.56522 | T24: =IF(M24=0,0,400-M24+S24) -> 400 | U24: =M24-S24 -> 0 | W24: =U24/INDEX(Analysis!$S$5:$Y$35,MATCH('Prod Plan 0115'!$A24,Analysis!$S$5:$S$35,0),3) -> 0 | AB24: =IF(U24=0,0,400-U24+AA24) -> 0
A25: ='Work Steps'!C24 -> SD4 | B25: ='Work Steps'!D24 -> 23 | C25: ='Work Steps'!F24 -> D4. Cushion Cover | D25: ='Work Steps'!G24 -> Add stitch to both zipper ends | E25: =INDEX(Analysis!$S$5:$Y$35,MATCH('Prod Plan 0115'!$A25,Analysis!$S$5:$S$35,0),4) -> 400 | G25: =INDEX(Analysis!$S$5:$Y$35,MATCH('Prod Plan 0115'!$A25,Analysis!$S$5:$S$35,0),7) -> 6.0263653 | L25: =IF(E25=0,0,400-E25+K25) -> 0 | M25: =E25-K25 -> 400 | N25: Jackie, Maricella | O25: =M25/INDEX(Analysis!$S$5:$Y$35,MATCH('Prod Plan 0115'!$A25,Analysis!$S$5:$S$35,0),3) -> 6.0263653 | P25: 2 | Q25: 0.25 | R25: =IF((Q25+(O25/P25)/24)+(0.5/24)>0.6875,0.6875,(Q25+(O25/P25)/24)+(0.5/24)) -> 0.39638261 | S25: =IF((((R25-Q25)*24)*P25)*INDEX(Analysis!$S$5:$Y$35,MATCH('Prod Plan 0115'!$A25,Analysis!$S$5:$S$35,0),3)>M25,M25,(((R25-Q25)*24)*P25)*INDEX(Analysis!$S$5:$Y$35,MATCH('Prod Plan 0115'!$A25,Analysis!$S$5:$S$35,0),3)) -> 400 | T25: =IF(M25=0,0,400-M25+S25) -> 400 | U25: =M25-S25 -> 0 | W25: =U25/INDEX(Analysis!$S$5:$Y$35,MATCH('Prod Plan 0115'!$A25,Analysis!$S$5:$S$35,0),3) -> 0 | AB25: =IF(U25=0,0,400-U25+AA25) -> 0
A26: ='Work Steps'!C25 -> SD5 | B26: ='Work Steps'!D25 -> 24 | C26: ='Work Steps'!F25 -> D5. Cushion Cover | D26: ='Work Steps'!G25 -> Sew the long sides closed | E26: =INDEX(Analysis!$S$5:$Y$35,MATCH('Prod Plan 0115'!$A26,Analysis!$S$5:$S$35,0),4) -> 400 | G26: =INDEX(Analysis!$S$5:$Y$35,MATCH('Prod Plan 0115'!$A26,Analysis!$S$5:$S$35,0),7) -> 3.3333333 | L26: =IF(E26=0,0,400-E26+K26) -> 0 | M26: =E26-K26 -> 400 | N26: All Sewing | O26: =M26/INDEX(Analysis!$S$5:$Y$35,MATCH('Prod Plan 0115'!$A26,Analysis!$S$5:$S$35,0),3) -> 3.3333333 | P26: 6 | Q26: =R25+((5/60)/24) -> 0.39985483 | R26: =IF((Q26+(O26/P26)/24)+(0.5/24)>0.6875,0.6875,(Q26+(O26/P26)/24)+(0.5/24)) -> 0.44383632 | S26: =IF((((R26-Q26)*24)*P26)*INDEX(Analysis!$S$5:$Y$35,MATCH('Prod Plan 0115'!$A26,Analysis!$S$5:$S$35,0),3)>M26,M26,(((R26-Q26)*24)*P26)*INDEX(Analysis!$S$5:$Y$35,MATCH('Prod Plan 0115'!$A26,Analysis!$S$5:$S$35,0),3)) -> 400 | T26: =IF(M26=0,0,400-M26+S26) -> 400 | U26: =M26-S26 -> 0 | W26: =U26/INDEX(Analysis!$S$5:$Y$35,MATCH('Prod Plan 0115'!$A26,Analysis!$S$5:$S$35,0),3) -> 0 | AB26: =IF(U26=0,0,400-U26+AA26) -> 0
A27: ='Work Steps'!C26 -> SD6 | B27: ='Work Steps'!D26 -> 25 | C27: ='Work Steps'!F26 -> D6.Cushion Cover | D27: ='Work Steps'!G26 -> Sew front panel with pockets to zipper panel | E27: =INDEX(Analysis!$S$5:$Y$35,MATCH('Prod Plan 0115'!$A27,Analysis!$S$5:$S$35,0),4) -> 400 | G27: =INDEX(Analysis!$S$5:$Y$35,MATCH('Prod Plan 0115'!$A27,Analysis!$S$5:$S$35,0),7) -> 3.3333333 | L27: =IF(E27=0,0,400-E27+K27) -> 0 | M27: =E27-K27 -> 400 | N27: All Sewing | O27: =M27/INDEX(Analysis!$S$5:$Y$35,MATCH('Prod Plan 0115'!$A27,Analysis!$S$5:$S$35,0),3) -> 3.3333333 | P27: 6 | Q27: =R26+((5/60)/24) -> 0.44730854 | R27: =IF((Q27+(O27/P27)/24)+(0.5/24)>0.6875,0.6875,(Q27+(O27/P27)/24)+(0.5/24)) -> 0.49129002 | S27: =IF((((R27-Q27)*24)*P27)*INDEX(Analysis!$S$5:$Y$35,MATCH('Prod Plan 0115'!$A27,Analysis!$S$5:$S$35,0),3)>M27,M27,(((R27-Q27)*24)*P27)*INDEX(Analysis!$S$5:$Y$35,MATCH('Prod Plan 0115'!$A27,Analysis!$S$5:$S$35,0),3)) -> 400 | T27: =IF(M27=0,0,400-M27+S27) -> 400 | U27: =M27-S27 -> 0 | W27: =U27/INDEX(Analysis!$S$5:$Y$35,MATCH('Prod Plan 0115'!$A27,Analysis!$S$5:$S$35,0),3) -> 0 | AB27: =IF(U27=0,0,400-U27+AA27) -> 0
A28: ='Work Steps'!C27 -> SD7 | B28: ='Work Steps'!D27 -> 26 | C28: ='Work Steps'!F27 -> D7. Cushion Cover | D28: ='Work Steps'!G27 -> Sew on the side panels | E28: =INDEX(Analysis!$S$5:$Y$35,MATCH('Prod Plan 0115'!$A28,Analysis!$S$5:$S$35,0),4) -> 400 | G28: =INDEX(Analysis!$S$5:$Y$35,MATCH('Prod Plan 0115'!$A28,Analysis!$S$5:$S$35,0),7) -> 3.3333333 | L28: =IF(E28=0,0,400-E28+K28) -> 0 | M28: =E28-K28 -> 400 | N28: All Sewing | O28: =M28/INDEX(Analysis!$S$5:$Y$35,MATCH('Prod Plan 0115'!$A28,Analysis!$S$5:$S$35,0),3) -> 3.3333333 | P28: 6 | Q28: =R27+((5/60)/24) -> 0.49476224 | R28: =IF((Q28+(O28/P28)/24)+(0.5/24)>0.6875,0.6875,(Q28+(O28/P28)/24)+(0.5/24)) -> 0.53874372 | S28: =IF((((R28-Q28)*24)*P28)*INDEX(Analysis!$S$5:$Y$35,MATCH('Prod Plan 0115'!$A28,Analysis!$S$5:$S$35,0),3)>M28,M28,(((R28-Q28)*24)*P28)*INDEX(Analysis!$S$5:$Y$35,MATCH('Prod Plan 0115'!$A28,Analysis!$S$5:$S$35,0),3)) -> 400 | T28: =IF(M28=0,0,400-M28+S28) -> 400 | U28: =M28-S28 -> 0 | W28: =U28/INDEX(Analysis!$S$5:$Y$35,MATCH('Prod Plan 0115'!$A28,Analysis!$S$5:$S$35,0),3) -> 0 | AB28: =IF(U28=0,0,400-U28+AA28) -> 0
A29: ='Work Steps'!C28 -> SD8 | B29: ='Work Steps'!D28 -> 27 | C29: ='Work Steps'!F28 -> D8. Cushion Cover | D29: ='Work Steps'!G28 -> Turn right side out | E29: =INDEX(Analysis!$S$5:$Y$35,MATCH('Prod Plan 0115'!$A29,Analysis!$S$5:$S$35,0),4) -> 400 | G29: =INDEX(Analysis!$S$5:$Y$35,MATCH('Prod Plan 0115'!$A29,Analysis!$S$5:$S$35,0),7) -> 3.3333333 | L29: =IF(E29=0,0,400-E29+K29) -> 0 | M29: =E29-K29 -> 400 | N29: All | O29: =M29/INDEX(Analysis!$S$5:$Y$35,MATCH('Prod Plan 0115'!$A29,Analysis!$S$5:$S$35,0),3) -> 3.3333333 | P29: 12 | Q29: =R28+((5/60)/24) -> 0.54221594 | R29: =IF((Q29+(O29/P29)/24)+(0.5/24)>0.6875,0.6875,(Q29+(O29/P29)/24)+(0.5/24)) -> 0.57462335 | S29: =IF((((R29-Q29)*24)*P29)*INDEX(Analysis!$S$5:$Y$35,MATCH('Prod Plan 0115'!$A29,Analysis!$S$5:$S$35,0),3)>M29,M29,(((R29-Q29)*24)*P29)*INDEX(Analysis!$S$5:$Y$35,MATCH('Prod Plan 0115'!$A29,Analysis!$S$5:$S$35,0),3)) -> 400 | T29: =IF(M29=0,0,400-M29+S29) -> 400 | U29: =M29-S29 -> 0 | W29: =U29/INDEX(Analysis!$S$5:$Y$35,MATCH('Prod Plan 0115'!$A29,Analysis!$S$5:$S$35,0),3) -> 0 | AB29: =IF(U29=0,0,400-U29+AA29) -> 0
A30: ='Work Steps'!C29 -> IFA | B30: ='Work Steps'!D29 -> 28 | C30: ='Work Steps'!F29 -> A. Inspection Quality | D30: ='Work Steps'!G29 -> Clean and inspect for any loose threads, missing, flag, ect. | E30: =INDEX(Analysis!$S$5:$Y$35,MATCH('Prod Plan 0115'!$A30,Analysis!$S$5:$S$35,0),4) -> 400 | G30: =INDEX(Analysis!$S$5:$Y$35,MATCH('Prod Plan 0115'!$A30,Analysis!$S$5:$S$35,0),7) -> 3.3333333 | L30: =IF(E30=0,0,400-E30+K30) -> 0 | M30: =E30-K30 -> 400 | N30: All | O30: =M30/INDEX(Analysis!$S$5:$Y$35,MATCH('Prod Plan 0115'!$A30,Analysis!$S$5:$S$35,0),3) -> 3.3333333 | P30: 12 | Q30: =R29+((5/60)/24) -> 0.57809557 | R30: =IF((Q30+(O30/P30)/24)+(0.5/24)>0.6875,0.6875,(Q30+(O30/P30)/24)+(0.5/24)) -> 0.61050298 | S30: =IF((((R30-Q30)*24)*P30)*INDEX(Analysis!$S$5:$Y$35,MATCH('Prod Plan 0115'!$A30,Analysis!$S$5:$S$35,0),3)>M30,M30,(((R30-Q30)*24)*P30)*INDEX(Analysis!$S$5:$Y$35,MATCH('Prod Plan 0115'!$A30,Analysis!$S$5:$S$35,0),3)) -> 400 | T30: =IF(M30=0,0,400-M30+S30) -> 400 | U30: =M30-S30 -> 0 | W30: =U30/INDEX(Analysis!$S$5:$Y$35,MATCH('Prod Plan 0115'!$A30,Analysis!$S$5:$S$35,0),3) -> 0 | AB30: =IF(U30=0,0,400-U30+AA30) -> 0
A31: ='Work Steps'!C30 -> IFB | B31: ='Work Steps'!D30 -> 29 | C31: ='Work Steps'!F30 -> B. Inspection Insert Foam | D31: ='Work Steps'!G30 -> Insert foam piece into the headrest. | E31: =INDEX(Analysis!$S$5:$Y$35,MATCH('Prod Plan 0115'!$A31,Analysis!$S$5:$S$35,0),4) -> 400 | G31: =INDEX(Analysis!$S$5:$Y$35,MATCH('Prod Plan 0115'!$A31,Analysis!$S$5:$S$35,0),7) -> 5.5555556 | L31: =IF(E31=0,0,400-E31+K31) -> 0 | M31: =E31-K31 -> 400 | O31: =M31/INDEX(Analysis!$S$5:$Y$35,MATCH('Prod Plan 0115'!$A31,Analysis!$S$5:$S$35,0),3) -> 5.5555556 | P31: 12 | Q31: =R30+((5/60)/24) -> 0.6139752 | R31: =IF((Q31+(O31/P31)/24)+(0.5/24)>0.6875,0.6875,(Q31+(O31/P31)/24)+(0.5/24)) -> 0.65409866 | S31: =IF((((R31-Q31)*24)*P31)*INDEX(Analysis!$S$5:$Y$35,MATCH('Prod Plan 0115'!$A31,Analysis!$S$5:$S$35,0),3)>M31,M31,(((R31-Q31)*24)*P31)*INDEX(Analysis!$S$5:$Y$35,MATCH('Prod Plan 0115'!$A31,Analysis!$S$5:$S$35,0),3)) -> 400 | T31: =IF(M31=0,0,400-M31+S31) -> 400 | U31: =M31-S31 -> 0 | W31: =U31/INDEX(Analysis!$S$5:$Y$35,MATCH('Prod Plan 0115'!$A31,Analysis!$S$5:$S$35,0),3) -> 0 | AB31: =IF(U31=0,0,400-U31+AA31) -> 0
A32: ='Work Steps'!C31 -> IFC | B32: ='Work Steps'!D31 -> 30 | C32: ='Work Steps'!F31 -> C. Inspection Bag | D32: ='Work Steps'!G31 -> Individually bagged into poly bag S-1997 Size: 9 x 24 | E32: =INDEX(Analysis!$S$5:$Y$35,MATCH('Prod Plan 0115'!$A32,Analysis!$S$5:$S$35,0),4) -> 400 | G32: =INDEX(Analysis!$S$5:$Y$35,MATCH('Prod Plan 0115'!$A32,Analysis!$S$5:$S$35,0),7) -> 3.3333333 | L32: =IF(E32=0,0,400-E32+K32) -> 0 | M32: =E32-K32 -> 400 | O32: =M32/INDEX(Analysis!$S$5:$Y$35,MATCH('Prod Plan 0115'!$A32,Analysis!$S$5:$S$35,0),3) -> 3.3333333 | P32: 12 | Q32: =R31+((5/60)/24) -> 0.65757088 | R32: =IF((Q32+(O32/P32)/24)+(0.5/24)>0.6875,0.6875,(Q32+(O32/P32)/24)+(0.5/24)) -> 0.6875 | S32: =IF((((R32-Q32)*24)*P32)*INDEX(Analysis!$S$5:$Y$35,MATCH('Prod Plan 0115'!$A32,Analysis!$S$5:$S$35,0),3)>M32,M32,(((R32-Q32)*24)*P32)*INDEX(Analysis!$S$5:$Y$35,MATCH('Prod Plan 0115'!$A32,Analysis!$S$5:$S$35,0),3)) -> 400 | T32: =IF(M32=0,0,400-M32+S32) -> 400 | U32: =M32-S32 -> 0 | W32: =U32/INDEX(Analysis!$S$5:$Y$35,MATCH('Prod Plan 0115'!$A32,Analysis!$S$5:$S$35,0),3) -> 0 | AB32: =IF(U32=0,0,400-U32+AA32) -> 0
A33: ='Work Steps'!C32 -> IFD | B33: ='Work Steps'!D32 -> 31 | C33: ='Work Steps'!F32 -> D. Inspection Pack | D33: ='Work Steps'!G32 -> Pack into cartons | E33: =INDEX(Analysis!$S$5:$Y$35,MATCH('Prod Plan 0115'!$A33,Analysis!$S$5:$S$35,0),4) -> 400 | G33: =INDEX(Analysis!$S$5:$Y$35,MATCH('Prod Plan 0115'!$A33,Analysis!$S$5:$S$35,0),7) -> 6.6666667 | L33: =IF(E33=0,0,400-E33+K33) -> 0 | M33: =E33-K33 -> 400 | O33: =M33/INDEX(Analysis!$S$5:$Y$35,MATCH('Prod Plan 0115'!$A33,Analysis!$S$5:$S$35,0),3) -> 6.6666667 | P33: 12 | Q33: =R32+((5/60)/24) -> 0.69097222 | R33: =IF((Q33+(O33/P33)/24)+(0.5/24)>0.6875,0.6875,(Q33+(O33/P33)/24)+(0.5/24)) -> 0.6875 | S33: =IF((((R33-Q33)*24)*P33)*INDEX(Analysis!$S$5:$Y$35,MATCH('Prod Plan 0115'!$A33,Analysis!$S$5:$S$35,0),3)>M33,M33,(((R33-Q33)*24)*P33)*INDEX(Analysis!$S$5:$Y$35,MATCH('Prod Plan 0115'!$A33,Analysis!$S$5:$S$35,0),3)) -> -60 | T33: =IF(M33=0,0,400-M33+S33) -> -60 | U33: =M33-S33 -> 460 | W33: =U33/INDEX(Analysis!$S$5:$Y$35,MATCH('Prod Plan 0115'!$A33,Analysis!$S$5:$S$35,0),3) -> 7.6666667 | AB33: =IF(U33=0,0,400-U33+AA33) -> -60

Sheet Prod Plan G
E1: Thursday - 1/15/2025 | M1: Friday - 1/16/2025 | U1: Saturday - 1/17/2025
A2: Task ID | B2: FB Task ID | C2: Component | D2: Task | E2: Units to Complete | F2: Names | G2: Hours Required | H2: # of People | I2: Start Time | J2: Finish Time | K2: Day Output | L2: Total Output | M2: Units to Complete | N2: Names | O2: Hours Required | P2: # of People | Q2: Start Time | R2: Finish Time | S2: Day Output | T2: Total Output | U2: Units to Complete | V2: Names | W2: Hours Required | X2: # of People | Y2: Start Time | Z2: Finish Time | AA2: Day Output | AB2: Total Output
A3: ='Work Steps'!C2 -> CFA1 | B3: ='Work Steps'!D2 -> 1 | C3: ='Work Steps'!F2 -> Fabric | D3: ='Work Steps'!G2 -> Cut Fabric | E3: =INDEX(Analysis!$S$5:$Y$35,MATCH('Prod Plan G'!$A3,Analysis!$S$5:$S$35,0),4) -> 0 | G3: =INDEX(Analysis!$S$5:$Y$35,MATCH('Prod Plan G'!$A3,Analysis!$S$5:$S$35,0),7) -> 0 | L3: =IF(E3=0,0,400-E3+K3) -> 0 | M3: =E3-K3 -> 0 | O3: =M3/INDEX(Analysis!$S$5:$Y$35,MATCH('Prod Plan G'!$A3,Analysis!$S$5:$S$35,0),3) -> 0 | T3: =IF(M3=0,0,400-M3+S3) -> 0 | U3: =M3-S3 -> 0 | W3: =U3/INDEX(Analysis!$S$5:$Y$35,MATCH('Prod Plan G'!$A3,Analysis!$S$5:$S$35,0),3) -> 0 | AB3: =IF(U3=0,0,400-U3+AA3) -> 0
A4: ='Work Steps'!C3 -> CTA1 | B4: ='Work Steps'!D3 -> 2 | C4: ='Work Steps'!F3 -> Trim | D4: ='Work Steps'!G3 -> Cut Velcro | E4: =INDEX(Analysis!$S$5:$Y$35,MATCH('Prod Plan G'!$A4,Analysis!$S$5:$S$35,0),4) -> 0 | G4: =INDEX(Analysis!$S$5:$Y$35,MATCH('Prod Plan G'!$A4,Analysis!$S$5:$S$35,0),7) -> 0 | L4: =IF(E4=0,0,400-E4+K4) -> 0 | M4: =E4-K4 -> 0 | O4: =M4/INDEX(Analysis!$S$5:$Y$35,MATCH('Prod Plan G'!$A4,Analysis!$S$5:$S$35,0),3) -> 0 | T4: =IF(M4=0,0,400-M4+S4) -> 0 | U4: =M4-S4 -> 0 | W4: =U4/INDEX(Analysis!$S$5:$Y$35,MATCH('Prod Plan G'!$A4,Analysis!$S$5:$S$35,0),3) -> 0 | AB4: =IF(U4=0,0,400-U4+AA4) -> 0
A5: ='Work Steps'!C4 -> PSA1 | B5: ='Work Steps'!D4 -> 3 | C5: ='Work Steps'!F4 -> Fabric | D5: ='Work Steps'!G4 -> Sew flag on panel | E5: =INDEX(Analysis!$S$5:$Y$35,MATCH('Prod Plan G'!$A5,Analysis!$S$5:$S$35,0),4) -> 0 | G5: =INDEX(Analysis!$S$5:$Y$35,MATCH('Prod Plan G'!$A5,Analysis!$S$5:$S$35,0),7) -> 0 | L5: =IF(E5=0,0,400-E5+K5) -> 0 | M5: =E5-K5 -> 0 | O5: =M5/INDEX(Analysis!$S$5:$Y$35,MATCH('Prod Plan G'!$A5,Analysis!$S$5:$S$35,0),3) -> 0 | T5: =IF(M5=0,0,400-M5+S5) -> 0 | U5: =M5-S5 -> 0 | W5: =U5/INDEX(Analysis!$S$5:$Y$35,MATCH('Prod Plan G'!$A5,Analysis!$S$5:$S$35,0),3) -> 0 | AB5: =IF(U5=0,0,400-U5+AA5) -> 0
A6: ='Work Steps'!C5 -> SA1 | B6: ='Work Steps'!D5 -> 4 | C6: ='Work Steps'!F5 -> A1. Small Velcro Pocket | D6: ='Work Steps'!G5 -> Hem short edge | E6: =INDEX(Analysis!$S$5:$Y$35,MATCH('Prod Plan G'!$A6,Analysis!$S$5:$S$35,0),4) -> 200 | G6: =INDEX(Analysis!$S$5:$Y$35,MATCH('Prod Plan G'!$A6,Analysis!$S$5:$S$35,0),7) -> 2.8145695 | L6: =IF(E6=0,0,400-E6+K6) -> 200 | M6: =E6-K6 -> 200 | O6: =M6/INDEX(Analysis!$S$5:$Y$35,MATCH('Prod Plan G'!$A6,Analysis!$S$5:$S$35,0),3) -> 2.8145695 | T6: =IF(M6=0,0,400-M6+S6) -> 200 | U6: =M6-S6 -> 200 | W6: =U6/INDEX(Analysis!$S$5:$Y$35,MATCH('Prod Plan G'!$A6,Analysis!$S$5:$S$35,0),3) -> 2.8145695 | AB6: =IF(U6=0,0,400-U6+AA6) -> 200
A7: ='Work Steps'!C6 -> SA2 | B7: ='Work Steps'!D6 -> 5 | C7: ='Work Steps'!F6 -> A2. Small Velcro Pocket | D7: ='Work Steps'!G6 -> Sew hook velcro | E7: =INDEX(Analysis!$S$5:$Y$35,MATCH('Prod Plan G'!$A7,Analysis!$S$5:$S$35,0),4) -> 400 | G7: =INDEX(Analysis!$S$5:$Y$35,MATCH('Prod Plan G'!$A7,Analysis!$S$5:$S$35,0),7) -> 10.457516 | L7: =IF(E7=0,0,400-E7+K7) -> 0 | M7: =E7-K7 -> 400 | O7: =M7/INDEX(Analysis!$S$5:$Y$35,MATCH('Prod Plan G'!$A7,Analysis!$S$5:$S$35,0),3) -> 10.457516 | T7: =IF(M7=0,0,400-M7+S7) -> 0 | U7: =M7-S7 -> 400 | W7: =U7/INDEX(Analysis!$S$5:$Y$35,MATCH('Prod Plan G'!$A7,Analysis!$S$5:$S$35,0),3) -> 10.457516 | AB7: =IF(U7=0,0,400-U7+AA7) -> 0
A8: ='Work Steps'!C7 -> SB1 | B8: ='Work Steps'!D7 -> 6 | C8: ='Work Steps'!F7 -> B1. Connector Strap | D8: ='Work Steps'!G7 -> Sew the panel together along the long sides | E8: =INDEX(Analysis!$S$5:$Y$35,MATCH('Prod Plan G'!$A8,Analysis!$S$5:$S$35,0),4) -> 0 | G8: =INDEX(Analysis!$S$5:$Y$35,MATCH('Prod Plan G'!$A8,Analysis!$S$5:$S$35,0),7) -> 0 | L8: =IF(E8=0,0,400-E8+K8) -> 0 | M8: =E8-K8 -> 0 | O8: =M8/INDEX(Analysis!$S$5:$Y$35,MATCH('Prod Plan G'!$A8,Analysis!$S$5:$S$35,0),3) -> 0 | T8: =IF(M8=0,0,400-M8+S8) -> 0 | U8: =M8-S8 -> 0 | W8: =U8/INDEX(Analysis!$S$5:$Y$35,MATCH('Prod Plan G'!$A8,Analysis!$S$5:$S$35,0),3) -> 0 | AB8: =IF(U8=0,0,400-U8+AA8) -> 0
A9: ='Work Steps'!C8 -> SB2 | B9: ='Work Steps'!D8 -> 7 | C9: ='Work Steps'!F8 -> B2. Connector Strap | D9: ='Work Steps'!G8 -> Turn inside out | E9: =INDEX(Analysis!$S$5:$Y$35,MATCH('Prod Plan G'!$A9,Analysis!$S$5:$S$35,0),4) -> 0 | G9: =INDEX(Analysis!$S$5:$Y$35,MATCH('Prod Plan G'!$A9,Analysis!$S$5:$S$35,0),7) -> 0 | L9: =IF(E9=0,0,400-E9+K9) -> 0 | M9: =E9-K9 -> 0 | O9: =M9/INDEX(Analysis!$S$5:$Y$35,MATCH('Prod Plan G'!$A9,Analysis!$S$5:$S$35,0),3) -> 0 | T9: =IF(M9=0,0,400-M9+S9) -> 0 | U9: =M9-S9 -> 0 | W9: =U9/INDEX(Analysis!$S$5:$Y$35,MATCH('Prod Plan G'!$A9,Analysis!$S$5:$S$35,0),3) -> 0 | AB9: =IF(U9=0,0,400-U9+AA9) -> 0
A10: ='Work Steps'!C9 -> SB3 | B10: ='Work Steps'!D9 -> 8 | C10: ='Work Steps'!F9 -> B3. Connector Strap | D10: ='Work Steps'!G9 -> Sew the 2 long sides of the connector Strap panel | E10: =INDEX(Analysis!$S$5:$Y$35,MATCH('Prod Plan G'!$A10,Analysis!$S$5:$S$35,0),4) -> 18 | G10: =INDEX(Analysis!$S$5:$Y$35,MATCH('Prod Plan G'!$A10,Analysis!$S$5:$S$35,0),7) -> 0.28548964 | L10: =IF(E10=0,0,400-E10+K10) -> 382 | M10: =E10-K10 -> 18 | O10: =M10/INDEX(Analysis!$S$5:$Y$35,MATCH('Prod Plan G'!$A10,Analysis!$S$5:$S$35,0),3) -> 0.28548964 | T10: =IF(M10=0,0,400-M10+S10) -> 382 | U10: =M10-S10 -> 18 | W10: =U10/INDEX(Analysis!$S$5:$Y$35,MATCH('Prod Plan G'!$A10,Analysis!$S$5:$S$35,0),3) -> 0.28548964 | AB10: =IF(U10=0,0,400-U10+AA10) -> 382
A11: ='Work Steps'!C10 -> SB4 | B11: ='Work Steps'!D10 -> 9 | C11: ='Work Steps'!F10 -> B4. Connector Strap | D11: ='Work Steps'!G10 -> Sew the connector strap to the small Velcro pocket, add the loop Velcro. | E11: =INDEX(Analysis!$S$5:$Y$35,MATCH('Prod Plan G'!$A11,Analysis!$S$5:$S$35,0),4) -> 400 | G11: =INDEX(Analysis!$S$5:$Y$35,MATCH('Prod Plan G'!$A11,Analysis!$S$5:$S$35,0),7) -> 7.8762307 | L11: =IF(E11=0,0,400-E11+K11) -> 0 | M11: =E11-K11 -> 400 | O11: =M11/INDEX(Analysis!$S$5:$Y$35,MATCH('Prod Plan G'!$A11,Analysis!$S$5:$S$35,0),3) -> 7.8762307 | T11: =IF(M11=0,0,400-M11+S11) -> 0 | U11: =M11-S11 -> 400 | W11: =U11/INDEX(Analysis!$S$5:$Y$35,MATCH('Prod Plan G'!$A11,Analysis!$S$5:$S$35,0),3) -> 7.8762307 | AB11: =IF(U11=0,0,400-U11+AA11) -> 0
A12: ='Work Steps'!C11 -> SB5 | B12: ='Work Steps'!D11 -> 10 | C12: ='Work Steps'!F11 -> B5. Connector Strap | D12: ='Work Steps'!G11 -> Close the sides of the small Velcro pocket. | E12: =INDEX(Analysis!$S$5:$Y$35,MATCH('Prod Plan G'!$A12,Analysis!$S$5:$S$35,0),4) -> 400 | G12: =INDEX(Analysis!$S$5:$Y$35,MATCH('Prod Plan G'!$A12,Analysis!$S$5:$S$35,0),7) -> 8.520956 | L12: =IF(E12=0,0,400-E12+K12) -> 0 | M12: =E12-K12 -> 400 | O12: =M12/INDEX(Analysis!$S$5:$Y$35,MATCH('Prod Plan G'!$A12,Analysis!$S$5:$S$35,0),3) -> 8.520956 | T12: =IF(M12=0,0,400-M12+S12) -> 0 | U12: =M12-S12 -> 400 | W12: =U12/INDEX(Analysis!$S$5:$Y$35,MATCH('Prod Plan G'!$A12,Analysis!$S$5:$S$35,0),3) -> 8.520956 | AB12: =IF(U12=0,0,400-U12+AA12) -> 0
A13: ='Work Steps'!C12 -> SB6 | B13: ='Work Steps'!D12 -> 11 | C13: ='Work Steps'!F12 -> B6. Connector Strap | D13: ='Work Steps'!G12 -> Cut threads, Turn right side out, Cut corners | E13: =INDEX(Analysis!$S$5:$Y$35,MATCH('Prod Plan G'!$A13,Analysis!$S$5:$S$35,0),4) -> 400 | G13: =INDEX(Analysis!$S$5:$Y$35,MATCH('Prod Plan G'!$A13,Analysis!$S$5:$S$35,0),7) -> 8.3076923 | L13: =IF(E13=0,0,400-E13+K13) -> 0 | M13: =E13-K13 -> 400 | O13: =M13/INDEX(Analysis!$S$5:$Y$35,MATCH('Prod Plan G'!$A13,Analysis!$S$5:$S$35,0),3) -> 8.3076923 | T13: =IF(M13=0,0,400-M13+S13) -> 0 | U13: =M13-S13 -> 400 | W13: =U13/INDEX(Analysis!$S$5:$Y$35,MATCH('Prod Plan G'!$A13,Analysis!$S$5:$S$35,0),3) -> 8.3076923 | AB13: =IF(U13=0,0,400-U13+AA13) -> 0
A14: ='Work Steps'!C13 -> SC1 | B14: ='Work Steps'!D13 -> 12 | C14: ='Work Steps'!F13 -> C1. Hanging Big Pocket | D14: ='Work Steps'!G13 -> Hem one short side | E14: =INDEX(Analysis!$S$5:$Y$35,MATCH('Prod Plan G'!$A14,Analysis!$S$5:$S$35,0),4) -> 400 | G14: =INDEX(Analysis!$S$5:$Y$35,MATCH('Prod Plan G'!$A14,Analysis!$S$5:$S$35,0),7) -> 3.4850088 | L14: =IF(E14=0,0,400-E14+K14) -> 0 | M14: =E14-K14 -> 400 | O14: =M14/INDEX(Analysis!$S$5:$Y$35,MATCH('Prod Plan G'!$A14,Analysis!$S$5:$S$35,0),3) -> 3.4850088 | T14: =IF(M14=0,0,400-M14+S14) -> 0 | U14: =M14-S14 -> 400 | W14: =U14/INDEX(Analysis!$S$5:$Y$35,MATCH('Prod Plan G'!$A14,Analysis!$S$5:$S$35,0),3) -> 3.4850088 | AB14: =IF(U14=0,0,400-U14+AA14) -> 0
... A33: ='Work Steps'!C32 -> IFD | B33: ='Work Steps'!D32 -> 31 | C33: ='Work Steps'!F32 -> D. Inspection Pack | D33: ='Work Steps'!G32 -> Pack into cartons | E33: =INDEX(Analysis!$S$5:$Y$35,MATCH('Prod Plan G'!$A33,Analysis!$S$5:$S$35,0),4) -> 400 | G33: =INDEX(Analysis!$S$5:$Y$35,MATCH('Prod Plan G'!$A33,Analysis!$S$5:$S$35,0),7) -> 6.6666667 | L33: =IF(E33=0,0,400-E33+K33) -> 0 | M33: =E33-K33 -> 400 | O33: =M33/INDEX(Analysis!$S$5:$Y$35,MATCH('Prod Plan G'!$A33,Analysis!$S$5:$S$35,0),3) -> 6.6666667 | T33: =IF(M33=0,0,400-M33+S33) -> 0 | U33: =M33-S33 -> 400 | W33: =U33/INDEX(Analysis!$S$5:$Y$35,MATCH('Prod Plan G'!$A33,Analysis!$S$5:$S$35,0),3) -> 6.6666667 | AB33: =IF(U33=0,0,400-U33+AA33) -> 0

Sheet Analysis
S2: TOTAL | X2: =SUM(X5:X35) -> 101.99869 | Y2: =SUM(Y5:Y35) -> 140.50448
A3: Average of Rate/Hour | B3: Column Labels
A4: Row Labels | B4: 00-Prod Dev | C4: Angelica | D4: Cindy | E4: Fransico | F4: Jackie | G4: Julieta | H4: Maricela | I4: Noe | J4: Oralia R | K4: Oralia S | L4: Patty | M4: Pilar | N4: Grand Total | S4: Task ID | T4: Dev Avg (pcs/hr) | U4: Actual Avg (pcs/hr) | V4: Balance | W4: Check | X4: Hours Dev | Y4: Hours Actual
A5: CFA1 | B5: 40 | N5: 40 | S5: =A5 -> CFA1 | T5: =N5 -> 40 | U5: =IF(ISERROR(AVERAGE(C5:M5)),N5,AVERAGE(C5:M5)) -> 40 | V5: =F41 -> 0 | W5: =D41 -> CFA1 | X5: =V5/T5 -> 0 | Y5: =V5/U5 -> 0
A6: CTA1 | B6: 1800 | N6: 1800 | S6: =A6 -> CTA1 | T6: =N6 -> 1800 | U6: =IF(ISERROR(AVERAGE(C6:M6)),N6,AVERAGE(C6:M6)) -> 1800 | V6: =F42 -> 0 | W6: =D42 -> CTA1 | X6: =V6/T6 -> 0 | Y6: =V6/U6 -> 0
A7: IFA | B7: 120 | N7: 120 | S7: =A7 -> IFA | T7: =N7 -> 120 | U7: =IF(ISERROR(AVERAGE(C7:M7)),N7,AVERAGE(C7:M7)) -> 120 | V7: =F43 -> 400 | W7: =D43 -> IFA | X7: =V7/T7 -> 3.3333333 | Y7: =V7/U7 -> 3.3333333
A8: IFB | B8: 72 | N8: 72 | S8: =A8 -> IFB | T8: =N8 -> 72 | U8: =IF(ISERROR(AVERAGE(C8:M8)),N8,AVERAGE(C8:M8)) -> 72 | V8: =F44 -> 400 | W8: =D44 -> IFB | X8: =V8/T8 -> 5.5555556 | Y8: =V8/U8 -> 5.5555556
A9: IFC | B9: 120 | N9: 120 | S9: =A9 -> IFC | T9: =N9 -> 120 | U9: =IF(ISERROR(AVERAGE(C9:M9)),N9,AVERAGE(C9:M9)) -> 120 | V9: =F45 -> 400 | W9: =D45 -> IFC | X9: =V9/T9 -> 3.3333333 | Y9: =V9/U9 -> 3.3333333
A10: IFD | B10: 60 | N10: 60 | S10: =A10 -> IFD | T10: =N10 -> 60 | U10: =IF(ISERROR(AVERAGE(C10:M10)),N10,AVERAGE(C10:M10)) -> 60 | V10: =F46 -> 400 | W10: =D46 -> IFD | X10: =V10/T10 -> 6.6666667 | Y10: =V10/U10 -> 6.6666667
A11: PSA1 | B11: 514.28571 | D11: 304.34783 | N11: 374.32712 | S11: =A11 -> PSA1 | T11: =N11 -> 374.32712 | U11: =IF(ISERROR(AVERAGE(C11:M11)),N11,AVERAGE(C11:M11)) -> 304.34783 | V11: =F47 -> 0 | W11: =D47 -> PSA1 | X11: =V11/T11 -> 0 | Y11: =V11/U11 -> 0
A12: SA1 | B12: 180 | C12: 94.117647 | J12: 48 | N12: 107.37255 | S12: =A12 -> SA1 | T12: =N12 -> 107.37255 | U12: =IF(ISERROR(AVERAGE(C12:M12)),N12,AVERAGE(C12:M12)) -> 71.058824 | V12: =F48 -> 200 | W12: =D48 -> SA1 | X12: =V12/T12 -> 1.8626735 | Y12: =V12/U12 -> 2.8145695
A13: SA2 | B13: 144 | F13: 60 | G13: 16.5 | N13: 73.5 | S13: =A13 -> SA2 | T13: =N13 -> 73.5 | U13: =IF(ISERROR(AVERAGE(C13:M13)),N13,AVERAGE(C13:M13)) -> 38.25 | V13: =F49 -> 400 | W13: =D49 -> SA2 | X13: =V13/T13 -> 5.4421769 | Y13: =V13/U13 -> 10.457516
A14: SB1 | B14: 300 | H14: 150 | J14: 72 | K14: 168 | N14: 172.5 | S14: =A14 -> SB1 | T14: =N14 -> 172.5 | U14: =IF(ISERROR(AVERAGE(C14:M14)),N14,AVERAGE(C14:M14)) -> 130 | V14: =F50 -> 0 | W14: =D50 -> SB1 | X14: =V14/T14 -> 0 | Y14: =V14/U14 -> 0
A15: SB2 | B15: 60 | E15: 48.679487 | I15: 48.679487 | L15: 46.230769 | N15: 49.59707 | S15: =A15 -> SB2 | T15: =N15 -> 49.59707 | U15: =IF(ISERROR(AVERAGE(C15:M15)),N15,AVERAGE(C15:M15)) -> 47.863248 | V15: =F51 -> 0 | W15: =D51 -> SB2 | X15: =V15/T15 -> 0 | Y15: =V15/U15 -> 0
A16: SB3 | B16: 144 | D16: 36.461538 | H16: 64.533333 | K16: 88.153846 | N16: 83.287179 | S16: =A16 -> SB3 | T16: =N16 -> 83.287179 | U16: =IF(ISERROR(AVERAGE(C16:M16)),N16,AVERAGE(C16:M16)) -> 63.049573 | V16: =F52 -> 18 | W16: =D52 -> SB3 | X16: =V16/T16 -> 0.2161197 | Y16: =V16/U16 -> 0.28548964
A17: SB4 | B17: 102.85714 | F17: 48.952381 | G17: 49.714286 | H17: 53.690476 | N17: 59.642857 | S17: =A17 -> SB4 | T17: =N17 -> 59.642857 | U17: =IF(ISERROR(AVERAGE(C17:M17)),N17,AVERAGE(C17:M17)) -> 50.785714 | V17: =F53 -> 400 | W17: =D53 -> SB4 | X17: =V17/T17 -> 6.7065868 | Y17: =V17/U17 -> 7.8762307
A18: SB5 | B18: 240 | F18: 46.829268 | G18: 30 | H18: 64 | N18: 95.207317 | S18: =A18 -> SB5 | T18: =N18 -> 95.207317 | U18: =IF(ISERROR(AVERAGE(C18:M18)),N18,AVERAGE(C18:M18)) -> 46.943089 | V18: =F54 -> 400 | W18: =D54 -> SB5 | X18: =V18/T18 -> 4.2013578 | Y18: =V18/U18 -> 8.520956
A19: SB6 | B19: 144 | F19: 44.444444 | L19: 50 | M19: 50 | N19: 72.111111 | S19: =A19 -> SB6 | T19: =N19 -> 72.111111 | U19: =IF(ISERROR(AVERAGE(C19:M19)),N19,AVERAGE(C19:M19)) -> 48.148148 | V19: =F55 -> 400 | W19: =D55 -> SB6 | X19: =V19/T19 -> 5.5469954 | Y19: =V19/U19 -> 8.3076923
A20: SC1 | B20: 211.76471 | C20: 156.92308 | J20: 72.631579 | N20: 147.10645 | S20: =A20 -> SC1 | T20: =N20 -> 147.10645 | U20: =IF(ISERROR(AVERAGE(C20:M20)),N20,AVERAGE(C20:M20)) -> 114.77733 | V20: =F56 -> 400 | W20: =D56 -> SC1 | X20: =V20/T20 -> 2.7191193 | Y20: =V20/U20 -> 3.4850088
A21: SC2 | B21: 102.85714 | C21: 70.421053 | J21: 70.8 | N21: 81.359398 | S21: =A21 -> SC2 | T21: =N21 -> 81.359398 | U21: =IF(ISERROR(AVERAGE(C21:M21)),N21,AVERAGE(C21:M21)) -> 70.610526 | V21: =F57 -> 400 | W21: =D57 -> SC2 | X21: =V21/T21 -> 4.9164572 | Y21: =V21/U21 -> 5.6648778
A22: SC3 | B22: 100 | C22: 78.705882 | F22: 126.92308 | J22: 62.470588 | N22: 92.024887 | S22: =A22 -> SC3 | T22: =N22 -> 92.024887 | U22: =IF(ISERROR(AVERAGE(C22:M22)),N22,AVERAGE(C22:M22)) -> 89.366516 | V22: =F58 -> 400 | W22: =D58 -> SC3 | X22: =V22/T22 -> 4.3466503 | Y22: =V22/U22 -> 4.4759494
A23: SC4 | B23: 144 | M23: 66.72 | N23: 105.36 | S23: =A23 -> SC4 | T23: =N23 -> 105.36 | U23: =IF(ISERROR(AVERAGE(C23:M23)),N23,AVERAGE(C23:M23)) -> 66.72 | V23: =F59 -> 400 | W23: =D59 -> SC4 | X23: =V23/T23 -> 3.7965072 | Y23: =V23/U23 -> 5.9952038
A24: SC5 | B24: 240 | C24: 82.677165 | J24: 69 | N24: 130.55906 | S24: =A24 -> SC5 | T24: =N24 -> 130.55906 | U24: =IF(ISERROR(AVERAGE(C24:M24)),N24,AVERAGE(C24:M24)) -> 75.838583 | V24: =F60 -> 400 | W24: =D60 -> SC5 | X24: =V24/T24 -> 3.0637477 | Y24: =V24/U24 -> 5.2743602
A25: SC6 | B25: 180 | C25: 60 | J25: 57.142857 | N25: 99.047619 | S25: =A25 -> SC6 | T25: =N25 -> 99.047619 | U25: =IF(ISERROR(AVERAGE(C25:M25)),N25,AVERAGE(C25:M25)) -> 58.571429 | V25: =F61 -> 400 | W25: =D61 -> SC6 | X25: =V25/T25 -> 4.0384615 | Y25: =V25/U25 -> 6.8292683
A26: SC7 | B26: 257.14286 | D26: 70.285714 | J26: 134.28571 | N26: 153.90476 | S26: =A26 -> SC7 | T26: =N26 -> 153.90476 | U26: =IF(ISERROR(AVERAGE(C26:M26)),N26,AVERAGE(C26:M26)) -> 102.28571 | V26: =F62 -> 400 | W26: =D62 -> SC7 | X26: =V26/T26 -> 2.5990099 | Y26: =V26/U26 -> 3.9106145
A27: SC8 | B27: 400 | C27: 58.252427 | F27: 97.826087 | H27: 87.272727 | N27: 160.83781 | S27: =A27 -> SC8 | T27: =N27 -> 160.83781 | U27: =IF(ISERROR(AVERAGE(C27:M27)),N27,AVERAGE(C27:M27)) -> 81.11708 | V27: =F63 -> 400 | W27: =D63 -> SC8 | X27: =V27/T27 -> 2.4869774 | Y27: =V27/U27 -> 4.9311439
A28: SD1 | B28: 36 | D28: 38.556701 | N28: 37.704467 | S28: =A28 -> SD1 | T28: =N28 -> 37.704467 | U28: =IF(ISERROR(AVERAGE(C28:M28)),N28,AVERAGE(C28:M28)) -> 38.556701 | V28: =F64 -> 300 | W28: =D64 -> SD1 | X28: =V28/T28 -> 7.9566168 | Y28: =V28/U28 -> 7.7807487
A29: SD2 | B29: 120 | D29: 76.673428 | N29: 91.115619 | S29: =A29 -> SD2 | T29: =N29 -> 91.115619 | U29: =IF(ISERROR(AVERAGE(C29:M29)),N29,AVERAGE(C29:M29)) -> 76.673428 | V29: =F65 -> 0 | W29: =D65 -> SD2 | X29: =V29/T29 -> 0 | Y29: =V29/U29 -> 0
A30: SD3 | B30: 200 | G30: 25.565217 | N30: 112.78261 | S30: =A30 -> SD3 | T30: =N30 -> 112.78261 | U30: =IF(ISERROR(AVERAGE(C30:M30)),N30,AVERAGE(C30:M30)) -> 25.565217 | V30: =F66 -> 400 | W30: =D66 -> SD3 | X30: =V30/T30 -> 3.5466461 | Y30: =V30/U30 -> 15.646259
A31: SD4 | B31: 60 | H31: 66.375 | N31: 63.1875 | S31: =A31 -> SD4 | T31: =N31 -> 63.1875 | U31: =IF(ISERROR(AVERAGE(C31:M31)),N31,AVERAGE(C31:M31)) -> 66.375 | V31: =F67 -> 400 | W31: =D67 -> SD4 | X31: =V31/T31 -> 6.330366 | Y31: =V31/U31 -> 6.0263653
A32: SD5 | B32: 120 | N32: 120 | S32: =A32 -> SD5 | T32: =N32 -> 120 | U32: =IF(ISERROR(AVERAGE(C32:M32)),N32,AVERAGE(C32:M32)) -> 120 | V32: =F68 -> 400 | W32: =D68 -> SD5 | X32: =V32/T32 -> 3.3333333 | Y32: =V32/U32 -> 3.3333333
A33: SD6 | B33: 120 | N33: 120 | S33: =A33 -> SD6 | T33: =N33 -> 120 | U33: =IF(ISERROR(AVERAGE(C33:M33)),N33,AVERAGE(C33:M33)) -> 120 | V33: =F69 -> 400 | W33: =D69 -> SD6 | X33: =V33/T33 -> 3.3333333 | Y33: =V33/U33 -> 3.3333333
A34: SD7 | B34: 120 | N34: 120 | S34: =A34 -> SD7 | T34: =N34 -> 120 | U34: =IF(ISERROR(AVERAGE(C34:M34)),N34,AVERAGE(C34:M34)) -> 120 | V34: =F70 -> 400 | W34: =D70 -> SD7 | X34: =V34/T34 -> 3.3333333 | Y34: =V34/U34 -> 3.3333333
A35: SD8 | B35: 120 | N35: 120 | S35: =A35 -> SD8 | T35: =N35 -> 120 | U35: =IF(ISERROR(AVERAGE(C35:M35)),N35,AVERAGE(C35:M35)) -> 120 | V35: =F71 -> 400 | W35: =D71 -> SD8 | X35: =V35/T35 -> 3.3333333 | Y35: =V35/U35 -> 3.3333333
A36: Grand Total | B36: 212.02928 | C36: 85.871036 | D36: 118.2379 | E36: 48.679487 | F36: 67.703948 | G36: 30.444876 | H36: 77.080288 | I36: 48.679487 | J36: 73.291342 | K36: 128.07692 | L36: 47.487179 | M36: 58.36 | N36: 127.12724
A38: Product | B38: (Multiple Items) | D38: Order Quantity | F38: 400
A40: Row Labels | B40: Sum of Completed Units | D40: Task ID | E40: Completed Units | F40: Balance
A41: CFA1 | B41: 400 | D41: =A41 -> CFA1 | E41: =B41 -> 400 | F41: =$F$38-E41 -> 0
A42: CTA1 | B42: 400 | D42: =A42 -> CTA1 | E42: =B42 -> 400 | F42: =$F$38-E42 -> 0
A43: IFA | D43: =A43 -> IFA | E43: =B43 -> 0 | F43: =$F$38-E43 -> 400
...

Sheet Production Data
A1: Product | B1: Date | C1: Name | D1: Task ID | E1: FB Task # | F1: Component | G1: Start Time | H1: Finish Time | I1: Completed Units | J1: Elapse Time | K1: Sew Time | L1: Rate/Hour
A2: Tenjam | B2: 46023 | C2: 00-Prod Dev | D2: CFA1 | E2: 1 | F2: Fabric | I2: 400 | L2: 40
A3: Tenjam | B3: 46023 | C3: 00-Prod Dev | D3: CTA1 | E3: 2 | F3: Trim | I3: 400 | L3: 1800
A4: Tenjam | B4: 46023 | C4: 00-Prod Dev | D4: IFA | E4: 28 | F4: A. Inspection Quality | L4: 120
A5: Tenjam | B5: 46023 | C5: 00-Prod Dev | D5: IFB | E5: 29 | F5: B. Inspection Insert Foam | L5: 72
A6: Tenjam | B6: 46023 | C6: 00-Prod Dev | D6: IFC | E6: 30 | F6: C. Inspection Bag | L6: 120
A7: Tenjam | B7: 46023 | C7: 00-Prod Dev | D7: IFD | E7: 31 | F7: D. Inspection Pack | L7: 60
A8: Tenjam | B8: 46023 | C8: 00-Prod Dev | D8: PSA1 | E8: 3 | F8: Fabric | L8: 514.28571
A9: Tenjam | B9: 46023 | C9: 00-Prod Dev | D9: SA1 | E9: 4 | F9: A1. Small Velcro Pocket | L9: 180
A10: Tenjam | B10: 46023 | C10: 00-Prod Dev | D10: SA2 | E10: 5 | F10: A2. Small Velcro Pocket | L10: 144
A11: Tenjam | B11: 46023 | C11: 00-Prod Dev | D11: SB1 | E11: 6 | F11: B1. Connector Strap | L11: 300
A12: Tenjam | B12: 46023 | C12: 00-Prod Dev | D12: SB2 | E12: 7 | F12: B2. Connector Strap | L12: 60
A13: Tenjam | B13: 46023 | C13: 00-Prod Dev | D13: SB3 | E13: 8 | F13: B3. Connector Strap | L13: 144
A14: Tenjam | B14: 46023 | C14: 00-Prod Dev | D14: SB4 | E14: 9 | F14: B4. Connector Strap | L14: 102.85714
A15: Tenjam | B15: 46023 | C15: 00-Prod Dev | D15: SB5 | E15: 10 | F15: B5. Connector Strap | L15: 240
... A32: Tenjam | B32: 46023 | C32: 00-Prod Dev | D32: SD8 | E32: 27 | F32: D8. Cushion Cover | L32: 120
A33: Tenjam - Blue | B33: 46034 | C33: Angelica | D33: SA1 | F33: A1 | G33: 0.35416667 | H33: 0.55208333 | I33: 400 | J33: =(H33-G33)*24 -> 4.75 | K33: =IF(AND(G33<0.4549,H33>0.4688),J33-0.5,J33) -> 4.25 | L33: =I33/K33 -> 94.117647
A34: Tenjam - Blue | B34: 46034 | C34: Angelica | D34: SC1 | F34: C1 | G34: 0.55208333 | H34: 0.59722222 | I34: 170 | J34: =(H34-G34)*24 -> 1.0833333 | K34: =IF(AND(G34<0.4549,H34>0.4688),J34-0.5,J34) -> 1.0833333 | L34: =I34/K34 -> 156.92308
A35: Tenjam - Blue | B35: 46034 | C35: Angelica | D35: SC2 | F35: C2 | G35: 0.59722222 | H35: 0.72916667 | I35: 223 | J35: =(H35-G35)*24 -> 3.1666667 | K35: =IF(AND(G35<0.4549,H35>0.4688),J35-0.5,J35) -> 3.1666667 | L35: =I35/K35 -> 70.421053
A36: Tenjam - Blue | B36: 46034 | C36: Cindy | D36: PSA1 | F36: A1 | G36: 0.39583333 | H36: 0.4375 | I36: 400 | J36: =(H36-G36)*24 -> 1 | K36: =IF(AND(G36<0.4549,H36>0.4688),J36-0.5,J36) -> 1 | L36: =I36/K36 -> 400
A37: Tenjam - Blue | B37: 46034 | C37: Cindy | D37: SB3 | F37: B3 | G37: 0.44444444 | H37: 0.64583333 | I37: 158 | J37: =(H37-G37)*24 -> 4.8333333 | K37: =IF(AND(G37<0.4549,H37>0.4688),J37-0.5,J37) -> 4.3333333 | L37: =I37/K37 -> 36.461538
A38: Tenjam - Blue | B38: 46034 | C38: Cindy | D38: SD2 | F38: D2 | G38: 0.64930556 | H38: 0.70833333 | I38: 100 | J38: =(H38-G38)*24 -> 1.4166667 | K38: =IF(AND(G38<0.4549,H38>0.4688),J38-0.5,J38) -> 1.4166667 | L38: =I38/K38 -> 70.588235
A39: Tenjam - Blue | B39: 46034 | C39: Fransico | D39: SB2 | F39: B2 | G39: 0.40625 | H39: 0.60763889 | I39: 133 | J39: =(H39-G39)*24 -> 4.8333333 | K39: =IF(AND(G39<0.4549,H39>0.4688),J39-0.5,J39) -> 4.3333333 | L39: =I39/K39 -> 30.692308
A40: Tenjam - Blue | B40: 46034 | C40: Jackie | D40: SB4 | F40: B4 | G40: 0.19791667 | H40: 0.22916667 | I40: 22 | J40: =(H40-G40)*24 -> 0.75 | K40: =IF(AND(G40<0.4549,H40>0.4688),J40-0.5,J40) -> 0.75 | L40: =I40/K40 -> 29.333333
A41: Tenjam - Blue | B41: 46034 | C41: Jackie | D41: SA2 | F41: A2 | G41: 0.4375 | H41: 0.69791667 | I41: 345 | J41: =(H41-G41)*24 -> 6.25 | K41: =IF(AND(G41<0.4549,H41>0.4688),J41-0.5,J41) -> 5.75 | L41: =I41/K41 -> 60
A42: Tenjam - Blue | B42: 46034 | C42: Julieta | D42: SA2 | F42: A2 | G42: 0.56944444 | H42: 0.70833333 | I42: 55 | J42: =(H42-G42)*24 -> 3.3333333 | K42: =IF(AND(G42<0.4549,H42>0.4688),J42-0.5,J42) -> 3.3333333 | L42: =I42/K42 -> 16.5
A43: Tenjam - Blue | B43: 46034 | C43: Julieta | D43: SB5 | F43: B5 | G43: 0.70833333 | H43: 0.72916667 | I43: 15 | J43: =(H43-G43)*24 -> 0.5 | K43: =IF(AND(G43<0.4549,H43>0.4688),J43-0.5,J43) -> 0.5 | L43: =I43/K43 -> 30
A44: Tenjam - Blue | B44: 46034 | C44: Maricela | D44: SB1 | F44: B1 | G44: 0.35416667 | H44: 0.46527778 | I44: 400 | J44: =(H44-G44)*24 -> 2.6666667 | K44: =IF(AND(G44<0.4549,H44>0.4688),J44-0.5,J44) -> 2.6666667 | L44: =I44/K44 -> 150
... A74: Tenjam - Blue | B74: 46035 | C74: Pilar | D74: SB6 | F74: B6 | G74: 0.52083333 | H74: 0.64583333 | I74: 150 | J74: =(H74-G74)*24 -> 3 | K74: =IF(AND(G74<0.4549,H74>0.4688),J74-0.5,J74) -> 3 | L74: =I74/K74 -> 50
A75: Tenjam - White | B75: 46036 | C75: Cindy | D75: SD1 | E75: 20 | F75: D1 | G75: 0.083333333 | H75: 0.1875 | I75: 100 | J75: =(H75-G75)*24 -> 2.5 | K75: =IF(AND(G75<0.4549,H75>0.4688),J75-0.5,J75) -> 2.5 | L75: =I75/K75 -> 40
A76: Tenjam - White | B76: 46036 | C76: Cindy | D76: PSA1 | E76: 3 | F76: Prep | G76: 0.27430556 | H76: 0.35416667 | I76: 400 | J76: =(H76-G76)*24 -> 1.9166667 | K76: =IF(AND(G76<0.4549,H76>0.4688),J76-0.5,J76) -> 1.9166667 | L76: =I76/K76 -> 208.69565
A77: Tenjam - White | B77: 46036 | C77: Cindy | D77: SD2 | E77: 21 | F77: D2 | G77: 0.36111111 | H77: 0.58333333 | I77: 400 | J77: =(H77-G77)*24 -> 5.3333333 | K77: =IF(AND(G77<0.4549,H77>0.4688),J77-0.5,J77) -> 4.8333333 | L77: =I77/K77 -> 82.758621
A78: Tenjam - White | B78: 46036 | C78: Fransico | D78: SB2 | E78: 7 | F78: B2 | G78: 0.32291667 | H78: 0.38541667 | I78: 100 | J78: =(H78-G78)*24 -> 1.5 | K78: =IF(AND(G78<0.4549,H78>0.4688),J78-0.5,J78) -> 1.5 | L78: =I78/K78 -> 66.666667
A79: Tenjam - White | B79: 46036 | C79: Noe | D79: SB2 | E79: 7 | F79: B2 | G79: 0.32291667 | H79: 0.38541667 | I79: 100 | J79: =(H79-G79)*24 -> 1.5 | K79: =IF(AND(G79<0.4549,H79>0.4688),J79-0.5,J79) -> 1.5 | L79: =I79/K79 -> 66.666667
A80: Tenjam - White | B80: 46036 | C80: Oralia R | D80: SB1 | E80: 6 | F80: B1 | G80: 0.30208333 | H80: 0.32291667 | I80: 36 | J80: =(H80-G80)*24 -> 0.5 | K80: =IF(AND(G80<0.4549,H80>0.4688),J80-0.5,J80) -> 0.5 | L80: =I80/K80 -> 72
A81: Tenjam - White | B81: 46036 | C81: Oralia R | D81: SA1 | E81: 4 | F81: A1 | G81: 0.50694444 | H81: 0.68055556 | I81: 200 | J81: =(H81-G81)*24 -> 4.1666667 | K81: =IF(AND(G81<0.4549,H81>0.4688),J81-0.5,J81) -> 4.1666667 | L81: =I81/K81 -> 48
A82: Tenjam - White | B82: 46036 | C82: Oralia S | D82: SB1 | E82: 6 | F82: B1 | G82: 0.25 | H82: 0.34027778 | I82: 364 | J82: =(H82-G82)*24 -> 2.1666667 | K82: =IF(AND(G82<0.4549,H82>0.4688),J82-0.5,J82) -> 2.1666667 | L82: =I82/K82 -> 168
A83: Tenjam - White | B83: 46036 | C83: Oralia S | D83: SB3 | E83: 8 | F83: B3 | G83: 0.50694444 | H83: 0.6875 | I83: 382 | J83: =(H83-G83)*24 -> 4.3333333 | K83: =IF(AND(G83<0.4549,H83>0.4688),J83-0.5,J83) -> 4.3333333 | L83: =I83/K83 -> 88.153846
A84: Tenjam - White | B84: 46036 | C84: Patty | D84: SB2 | E84: 7 | F84: B2 | G84: 0.32291667 | H84: 0.45833333 | I84: 200 | J84: =(H84-G84)*24 -> 3.25 | K84: =IF(AND(G84<0.4549,H84>0.4688),J84-0.5,J84) -> 3.25 | L84: =I84/K84 -> 61.538462

Sheet Work Steps
